Workbook
Name Bar_C: Inputs!$D$224
Name Bar_D3s: Inputs!$D$228
Name Bar_DA: Inputs!$D$225
Name Bar_DB: Inputs!$D$226
Name Bar_MD: Inputs!$D$227
Name Bar_Mk: Inputs!$D$229
Name Bm_Area: Inputs!$D$222
Name Bm_Bf: Inputs!$D$41
Name Bm_D: Inputs!$D$40
Name Bm_First: Inputs!$D$39
Name Bm_Gap1: Inputs!$D$45
Name Bm_Hmin: Inputs!$D$42
Name Bm_N: Inputs!$D$37
Name Bm_S: Inputs!$D$38
Name Bm_Type: Inputs!$D$36
Name Bm1_dCL: 'Profile & Deck'!$I$29
Name Bm1_dMin: 'Profile & Deck'!$L$29
Name Bm1_FL: 'Profile & Deck'!$D$29
Name Bm1_FR: 'Profile & Deck'!$F$29
Name Bm1_Off: 'Profile & Deck'!$C$29
Name Bm1_Raise: Inputs!$D$43
Name Bm2_dCL: 'Profile & Deck'!$I$30
Name Bm2_dMin: 'Profile & Deck'!$L$30
Name Bm2_FL: 'Profile & Deck'!$D$30
Name Bm2_FR: 'Profile & Deck'!$F$30
Name Bm2_Off: 'Profile & Deck'!$C$30
Name Bm2_Raise: Inputs!$D$44
Name Build_Fingerprint: Cover!$C$11
Name Build_Model: Cover!$C$14
Name Build_Time: Cover!$C$13
Name Clr_Cover: Clearance!$F$11
Name Clr_Margin: Clearance!$F$10
Name Clr_Min: Clearance!$F$7
Name Clr_Sta: Clearance!$F$8
Name Clr_Status: Clearance!$F$12
Name Deck_C: Inputs!$D$29
Name Deck_Crown: Inputs!$D$31
Name Deck_dL: 'Profile & Deck'!$D$24
Name Deck_dR: 'Profile & Deck'!$D$25
Name Deck_Mode: Inputs!$D$27
Name Deck_T: Inputs!$D$30
Name Deck_Uni: Inputs!$D$32
Name Deck_W: Inputs!$D$28
Name Deck_YL: 'Profile & Deck'!$D$22
Name Deck_YR: 'Profile & Deck'!$D$23
Name Des_BevelLimit: Inputs!$D$220
Name Des_ConcClass: Inputs!$D$216
Name Des_DimP: Inputs!$D$221
Name Des_FGEInc: Inputs!$D$223
Name Des_PadType: Inputs!$D$219
Name Des_Pattern: Inputs!$D$217
Name Des_PlanCase: Inputs!$D$218
Name EB1_BmBrg: Inputs!$D$110
Name EB1_BmClr: Inputs!$D$109
Name EB1_BW: Inputs!$D$107
Name EB1_BwDrop: Inputs!$D$111
Name EB1_BwH0: Substructure!$F$82
Name EB1_BwTop0: Substructure!$F$76
Name EB1_BwTopL: Substructure!$F$75
Name EB1_BwTopR: Substructure!$F$77

Sheet Cover
B2: B4 Pedestrian Bridge - Geometry and CAD Tables
B3: =TB_Project&" | "&TB_Structure -> D2 I-95 Pedestrian Bridge | B4 pedestrian bridge - 2 x FIB-36, two simple spans
B5: Geometry authority | C5: Colab geometry notebook Bridge_Geometry_2 Beam_V2.ipynb (CONFIG + BridgeModel). This workbook reproduces its equations in Excel; the CAD model and these CAD tables are built from it, never the reverse.
B6: Beam design data | C6: Saved results of the two registered Mathcad runs (Span 1, Span 2). Mathcad was not recalculated.
B7: Template methods | C7: Where the notebook is silent (Table of Beam Variables bar dimensions, Dim L/R, build-up case, beveled plates) the BCC example workbook's formulas are used and flagged on the Method tabs.
B8: QC status | C8: =QC_Overall&" ("&QC_Counts&")" -> PASS (181 pass / 0 fail / 1 check)
B9: Input sync | C9: =IF(Inputs_Edited=0,"Inputs match the notebook build: tables and Method-tab charts show the notebook geometry.",Inputs_Edited&" input(s) edited since the build. Tables and charts follow the edits, which no longer match the notebook. Update the notebook CONFIG and rebuild.") -> Inputs match the notebook build: tables and Method-tab charts show the notebook geometry.
B10: Rebuild | C10: C:\github\D2MPDB\.venv\Scripts\python.exe scripts\build_geometry_cad_tables.py (rebuilds, recalculates in Excel, verifies)
B11: Build fingerprint | C11: 8291d84b1993a439602b
B12: Generator version | C12: 1.1.1
B13: Built | C13: 2026-10-19 12:13
B14: Notebook model ID | C14: e9b41b8eaf
B16: Sources
B17: Geometry notebook | C17: Bridge_Geometry_2 Beam_V2.ipynb (lf_text) SHA-256 4ccd84724ab53d45b9e2bcc7201ece64c0406f8b72e9772d8df5456b0199310b
B18: Roadway XML | C18: Geometry Report.xml SHA-256 9880ef7adeeac4228666146f5d5bb4dd17ef93f66ffeaf465a2c813eb69489e4
B19: Mathcad Span 1 | C19: project_current/mathcad/PrestressedBeamV6.2_Pedestrian_2Beam_Span1.xmcd SHA-256 a6b0f967d271c193591d477e219ac66f98b72309d19958a04c6cd08e575a8dcd
B20: Mathcad Span 2 | C20: project_current/mathcad/PrestressedBeamV6.2_Pedestrian_2Beam_Span2.xmcd SHA-256 182e3471f169d3a379c437ad12f359d567813bd4631bcc0b82e78ad860fa91b8
B22: Tabs
B23: Inputs | C23: All inputs with provenance (notebook CONFIG, Mathcad saved results, designer/template constants).
B24: Inputs Method | C24: Method for Inputs: equations, explanation, schematics and live charts.
B25: Profile & Deck | C25: PGL grades, deck edges, beam offsets and haunch check points.
B26: Profile & Deck Method | C26: Method for Profile & Deck: equations, explanation, schematics and live charts.
B27: Beam Geometry | C27: Physical beam ends, bearings, chords; Dims J, K, P, L and shortening R.
B28: Beam Geometry Method | C28: Method for Beam Geometry: equations, explanation, schematics and live charts.
B29: Camber & Haunch | C29: Common support drop D, build-up Dims B/C/D, minimum haunch, Mathcad deflections.
B30: Camber & Haunch Method | C30: Method for Camber & Haunch: equations, explanation, schematics and live charts.
B31: FGE | C31: Finished grade elevations at every line and station.
B32: FGE Method | C32: Method for FGE: equations, explanation, schematics and live charts.
B33: Bearing Seats | C33: Seat planes, slopes, pedestal tops and corners, bearing plate data.
B34: Bearing Seats Method | C34: Method for Bearing Seats: equations, explanation, schematics and live charts.
... B52: QC Method | C52: Method for QC: equations, explanation, schematics and live charts.
B54: Cell legend
B55: Input (generated from notebook / Mathcad)
B56: Calculated in this tab
B57: Linked from another tab
B58: PASS
B59: FAIL
B60: CHECK / review
B62: Open items
C63: - Both backwall tops use two straight 2% slopes (D-053), 4-1/4 in below their FFBW deck-top lines. Ramp slabs thicken locally (about 4.05-4.95 in at checked points). Recheck profile edits and reconcile downstream drawings, quantities and backwall/slab design.
...

Sheet Inputs
A1: Inputs
A2: Blue values on yellow are inputs. Every geometry input is generated from the Colab geometry notebook CONFIG (the geometry authority); beam-design inputs come from the saved Mathcad runs. Edit the notebook and rebuild rather than editing these cells: the tables and Method-tab charts follow any edit, and the banner on every Method tab and QC report that inputs no longer match the notebook build.
A4: Title block (fill in)
B5: Parameter | C5: Symbol | D5: Value | E5: Unit | F5: Workbook name | G5: Source / note
B6: Project | D6: D2 I-95 Pedestrian Bridge | F6: TB_Project | G6: Project journal name; edit as needed
B7: Structure | D7: B4 pedestrian bridge - 2 x FIB-36, two simple spans | F7: TB_Structure | G7: FreeCAD model / Mathcad beam type; edit as needed
B8: Job No. | F8: TB_JobNo | G8: Not in project sources - enter
B9: Calculated by | F9: TB_CalcBy | G9: Enter
B10: Date (calculated) | F10: TB_CalcDate | G10: Enter
B11: Checked by | F11: TB_CheckBy | G11: Enter
B12: Date (checked) | F12: TB_CheckDate | G12: Enter
A14: Profile - CONFIG['profile']
B15: Parameter | C15: Symbol | D15: Value | E15: Unit | F15: Workbook name | G15: Source / note
B16: Profile mode (brokeback or parabolic) | C16: mode | D16: brokeback | F16: Prof_Mode | G16: Notebook CONFIG profile.mode
B17: Profile start station (FFBW End Bent 1) | C17: s0 | D17: 1593.22 | E17: ft | F17: Prof_Sta0 | G17: Notebook CONFIG profile.start_sta_ft
B18: Profile end station (FFBW End Bent 2) | C18: s1 | D18: 1805.47 | E18: ft | F18: Prof_Sta1 | G18: Notebook CONFIG profile.end_sta_ft
B19: Start elevation | C19: z0 | D19: 47.661 | E19: ft | F19: Prof_Z0 | G19: Notebook CONFIG profile.start_elev_ft
B20: End elevation | C20: z1 | D20: 47.673 | E20: ft | F20: Prof_Z1 | G20: Notebook CONFIG profile.end_elev_ft
B21: Tangent intersection station (PI) | C21: sPI | D21: 1700.57 | E21: ft | F21: Prof_PISta | G21: Notebook CONFIG profile.intersection_sta_ft
B22: Nominal tangent grade (brokeback) | C22: g | D22: 0.005 | E22: ft/ft | F22: Prof_Gnom | G22: Notebook CONFIG profile.nominal_grade
B23: Grade change (parabolic mode only) | C23: dg | D23: -0.01 | E23: ft/ft | F23: Prof_dG | G23: Notebook CONFIG profile.parabolic_grade_change
A25: Deck - CONFIG['deck']
B26: Parameter | C26: Symbol | D26: Value | E26: Unit | F26: Workbook name | G26: Source / note
B27: Deck mode (crowned or uniform) | C27: mode | D27: crowned | F27: Deck_Mode | G27: Notebook CONFIG deck.mode. Transition mode is not implemented in this workbook (QC fails).
B28: Deck width | C28: W | D28: 13.583333 | E28: ft | F28: Deck_W | G28: Notebook CONFIG deck.width_ft (13 ft 7 in from DXF *D5380)
B29: Deck center offset from PGL | C29: yc | D29: 0 | E29: ft | F29: Deck_C | G29: Notebook CONFIG deck.center_offset_ft
B30: Deck thickness | C30: td | D30: 0.5 | E30: ft | F30: Deck_T | G30: Notebook CONFIG deck.thickness_ft
B31: Crown slope (each side, away from PGL) | C31: sc | D31: -0.02 | E31: ft/ft | F31: Deck_Crown | G31: Notebook CONFIG deck.crown_slope
B32: Uniform cross slope (uniform mode only) | C32: su | D32: -0.02 | E32: ft/ft | F32: Deck_Uni | G32: Notebook CONFIG deck.uniform_slope
A34: Beams - CONFIG['beams']
B35: Parameter | C35: Symbol | D35: Value | E35: Unit | F35: Workbook name | G35: Source / note
B36: Beam type | D36: FIB-36 | F36: Bm_Type | G36: Mathcad BeamType (notebook models the FIB-36 outline)
B37: Number of beams | C37: N | D37: 2 | F37: Bm_N | G37: Notebook CONFIG beams.count (table layout is generated for this count)
B38: Beam spacing | C38: S | D38: 8.5833333 | E38: ft | F38: Bm_S | G38: Notebook CONFIG beams.spacing_ft
B39: First beam offset (blank = centered on PGL) | C39: y1 | E39: ft | F39: Bm_First | G39: Notebook CONFIG beams.first_offset_ft
B40: Beam depth | C40: db | D40: 3 | E40: ft | F40: Bm_D | G40: Notebook CONFIG beams.depth_ft
B41: Top flange width | C41: bf | D41: 48 | E41: in | F41: Bm_Bf | G41: Notebook CONFIG beams.top_flange_width_in
B42: Minimum haunch (at any flange point) | C42: hmin | D42: 0.5 | E42: in | F42: Bm_Hmin | G42: Notebook CONFIG beams.minimum_haunch_in
B43: Beam 1 vertical raise | C43: r1 | D43: 0 | E43: in | F43: Bm1_Raise | G43: Notebook CONFIG beams.raise_in
B44: Beam 2 vertical raise | C44: r2 | D44: 0 | E44: in | F44: Bm2_Raise | G44: Notebook CONFIG beams.raise_in
...

Sheet Inputs Method
B1: Inputs - Method
B2: Where every input comes from and how the workbook is kept consistent with the notebook
B3: =IF(Inputs_Edited=0,"LIVE Charts, tables and the numbers quoted in this text are workbook formulas. Inputs match the notebook build (model "&Build_Model&", built "&Build_Time&").",Inputs_Edited&" INPUT(S) EDITED SINCE THE NOTEBOOK BUILD The charts and tables follow the edited inputs, which no longer match the geometry notebook (QC "&QC_Overall&"). Change the notebook CONFIG and rebuild.") -> LIVE Charts, tables and the numbers quoted in this text are workbook formulas. Inputs match the notebook build (model e9b41b8eaf, built 2026-10-19 12:13).
B5: 1. Authority and data flow
B6: The Colab geometry notebook (Bridge_Geometry_2 Beam_V2.ipynb) is the source of truth for all bridge geometry. Its CONFIG dictionary and BridgeModel equations define the profile, deck, beam layout, bearings, caps, pedestals and piles. The FreeCAD model and these CAD tables are built from the notebook, never the reverse. The generator executes the notebook cells, writes CONFIG into this tab, and writes every calculation as an Excel formula.
B20: Figure 1. Source-to-table flow. Each arrow is a formula chain you can trace with Excel "Trace Precedents".
B22: 2. Sign conventions and units
B23: • Stations s increase from End Bent 1 to End Bent 2 (ft). Offsets y are measured from the PGL, positive to the right looking up-station (ft).
B24: • Elevations z are in feet on the project datum. Inputs ending in "in" are inches; slopes and grades are ft/ft.
B25: • Deflections and camber are in inches, positive upward (Mathcad convention). The camber C is the peak upward value at midspan.
B26: • Workbook names (Formulas > Name Manager) mirror the notebook keys, for example Prof_Sta0 = CONFIG["profile"]["start_sta_ft"].
B28: 3. Mathcad beam-design values
B29: Beam-design inputs are the saved results stored in the two registered Mathcad runs. The generator parses the worksheet XML and reads each result by variable name; Mathcad is not recalculated. The notebook camber input equals the Mathcad NetCamber:
B33: ="Span 1: C = "&TEXT(Sp1_C,"0.000000")&" in; Span 2: C = "&TEXT(Sp2_C,"0.000000")&" in. QC confirms the deflection sum, the Mathcad NetCamber and the notebook CONFIG camber agree." -> Span 1: C = 0.124593 in; Span 2: C = 0.567171 in. QC confirms the deflection sum, the Mathcad NetCamber and the notebook CONFIG camber agree.
B34: Symbol | C34: Meaning | H34: Workbook name / location | K34: Units / value
B35: C | C35: Net camber at 120 days after all dead load | H35: Sp1_C, Sp2_C (Inputs) | K35: in
B36: Δ120 | C36: 120-day prestress + beam weight deflection (max) | H36: MC1_D120, MC2_D120 | K36: in
B37: ΔDL,nc | C37: Non-composite dead load (deck pour) deflection (min) | H37: MC1_Dnc, MC2_Dnc | K37: in
B38: ΔDL,c | C38: Composite dead load (barrier) deflection (min) | H38: MC1_Dc, MC2_Dc | K38: in
B39: ψ, εsh | C39: Creep coefficient and shrinkage strain at 120 days | H39: MC1_Psi, MC1_Esh ... | K39: -
B42: 4. Designer assignments and template constants
B43: A few table entries are not geometry and are not in Mathcad: concrete class, strand pattern number, plan view case and pad type. They are explicit inputs at the bottom of the Inputs tab. Standard bar-bending constants for the Table of Beam Variables are taken from the BCC example workbook formulas so the tables are produced the same way as before.
B45: 5. Keeping it current
B46: • Change geometry in the notebook CONFIG, then run: .venv\Scripts\python.exe scripts\build_geometry_cad_tables.py
B47: • The script rebuilds every tab, has Excel recalculate, and verifies the results against the notebook before saving.
B48: • Every figure that shows project values is a live Excel chart of the workbook cells; its figure data (formulas) sits to the right of the text on each Method tab. Pictures are limited to equations and label-only schematics.
B49: • Editing a blue input here recalculates the tables and charts. The banner at the top of every Method tab, the Cover and the QC tab then report that inputs differ from the notebook build, and QC flags any result that no longer matches the notebook.
B50: • Build fingerprint 8291d84b1993a439602b; notebook model ID e9b41b8eaf. The regression test fails if any source or the generator changes without a rebuild.

Sheet Profile & Deck
A1: Profile & Deck | K1: Project | L1: =""&TB_Project -> D2 I-95 Pedestrian Bridge
A2: PGL profile, deck cross slope, beam offsets and haunch check points | K2: Job No. | L2: =""&TB_JobNo
K3: Calc. by / date | L3: =TB_CalcBy&" "&TB_CalcDate
K4: Check. by / date | L4: =TB_CheckBy&" "&TB_CheckDate
A6: Profile constants
B7: Parameter | C7: Symbol | D7: Value | E7: Unit | F7: Workbook name | G7: Source / note
B8: Profile length | C8: L | D8: =Prof_Sta1-Prof_Sta0 -> 212.25 | E8: ft | F8: Prof_L | G8: s1 - s0
B9: PI elevation (brokeback) | C9: zPI | D9: =(Prof_Z0+Prof_Gnom*(Prof_PISta-Prof_Sta0)+Prof_Z1+Prof_Gnom*(Prof_Sta1-Prof_PISta))/2 -> 48.197625 | E9: ft | F9: Prof_PIZ | G9: Average of the two tangents projected to the PI
B10: Grade 1 (entering) | C10: g1 | D10: =IF(Prof_Mode="parabolic",(Prof_Z1-Prof_Z0)/Prof_L-Prof_dG/2,(Prof_PIZ-Prof_Z0)/(Prof_PISta-Prof_Sta0)) -> 0.0049988356 | E10: ft/ft | F10: Prof_G1 | G10: Notebook BridgeModel.__init__
B11: Grade 2 (leaving) | C11: g2 | D11: =IF(Prof_Mode="parabolic",Prof_G1+Prof_dG,(Prof_Z1-Prof_PIZ)/(Prof_Sta1-Prof_PISta)) -> -0.0050011916 | E11: ft/ft | F11: Prof_G2 | G11: Notebook BridgeModel.__init__
B12: Parabolic coefficient (0 for brokeback) | C12: kq | D12: =IF(Prof_Mode="parabolic",0.5*(Prof_G2-Prof_G1)/Prof_L,0) -> 0 | E12: 1/ft | F12: Prof_Kq | G12: z = z0 + g1 x + kq x^2
A14: PGL at control stations
B15: Control point | C15: Station (ft) | D15: PGL (ft) | E15: Station label
B16: FFBW End Bent 1 (profile start) | C16: =Prof_Sta0 -> 1593.22 | D16: =IF(Prof_Mode="parabolic",Prof_Z0+Prof_G1*((C16)-Prof_Sta0)+Prof_Kq*((C16)-Prof_Sta0)^2,IF((C16)<=Prof_PISta,Prof_Z0+Prof_G1*((C16)-Prof_Sta0),Prof_PIZ+Prof_G2*((C16)-Prof_PISta))) -> 47.661 | E16: =TEXT(INT(ROUND(C16*100,0)/10000),"0")&"+"&TEXT(MOD(ROUND(C16*100,0),10000)/100,"00.00") -> 15+93.22
B17: Tangent intersection (PI) | C17: =Prof_PISta -> 1700.57 | D17: =IF(Prof_Mode="parabolic",Prof_Z0+Prof_G1*((C17)-Prof_Sta0)+Prof_Kq*((C17)-Prof_Sta0)^2,IF((C17)<=Prof_PISta,Prof_Z0+Prof_G1*((C17)-Prof_Sta0),Prof_PIZ+Prof_G2*((C17)-Prof_PISta))) -> 48.197625 | E17: =TEXT(INT(ROUND(C17*100,0)/10000),"0")&"+"&TEXT(MOD(ROUND(C17*100,0),10000)/100,"00.00") -> 17+00.57
B18: FFBW End Bent 2 (profile end) | C18: =Prof_Sta1 -> 1805.47 | D18: =IF(Prof_Mode="parabolic",Prof_Z0+Prof_G1*((C18)-Prof_Sta0)+Prof_Kq*((C18)-Prof_Sta0)^2,IF((C18)<=Prof_PISta,Prof_Z0+Prof_G1*((C18)-Prof_Sta0),Prof_PIZ+Prof_G2*((C18)-Prof_PISta))) -> 47.673 | E18: =TEXT(INT(ROUND(C18*100,0)/10000),"0")&"+"&TEXT(MOD(ROUND(C18*100,0),10000)/100,"00.00") -> 18+05.47
A20: Deck edges
B21: Parameter | C21: Symbol | D21: Value | E21: Unit | F21: Workbook name | G21: Source / note
B22: Left deck edge (coping) offset | D22: =Deck_C-Deck_W/2 -> -6.7916667 | E22: ft | F22: Deck_YL | G22: Offsets measured from the PGL, + to the right looking up-station
B23: Right deck edge (coping) offset | D23: =Deck_C+Deck_W/2 -> 6.7916667 | E23: ft | F23: Deck_YR
B24: Deck cross-slope drop at left edge | D24: =IF(Deck_Mode="uniform",Deck_Uni*(Deck_YL),Deck_Crown*ABS(Deck_YL)) -> -0.13583333 | E24: ft | F24: Deck_dL | G24: delta(y)
B25: Deck cross-slope drop at right edge | D25: =IF(Deck_Mode="uniform",Deck_Uni*(Deck_YR),Deck_Crown*ABS(Deck_YR)) -> -0.13583333 | E25: ft | F25: Deck_dR | G25: delta(y)
A27: Beam lines and haunch check points (flange edges, CL and any crown point on the flange)
B28: Beam | C28: Offset y (ft) | D28: Left flange edge | E28: CL | F28: Right flange edge | G28: Crown point on flange | H28: delta left (ft) | I28: delta CL (ft) | J28: delta right (ft) | K28: delta crown pt (ft) | L28: delta min (ft)
B29: Beam 1 | C29: =IF(ISNUMBER(Bm_First),Bm_First,-(Bm_Gap1)/2) -> -4.2916667 | D29: =C29-Bm_Bf/24 -> -6.2916667 | E29: =C29 -> -4.2916667 | F29: =C29+Bm_Bf/24 -> -2.2916667 | G29: =MAX(D29,MIN(0,F29)) -> -2.2916667 | H29: =IF(Deck_Mode="uniform",Deck_Uni*(D29),Deck_Crown*ABS(D29)) -> -0.12583333 | I29: =IF(Deck_Mode="uniform",Deck_Uni*(E29),Deck_Crown*ABS(E29)) -> -0.085833333 | J29: =IF(Deck_Mode="uniform",Deck_Uni*(F29),Deck_Crown*ABS(F29)) -> -0.045833333 | K29: =IF(Deck_Mode="uniform",Deck_Uni*(G29),Deck_Crown*ABS(G29)) -> -0.045833333 | L29: =MIN(H29:K29) -> -0.12583333
B30: Beam 2 | C30: =Bm1_Off+Bm_Gap1 -> 4.2916667 | D30: =C30-Bm_Bf/24 -> 2.2916667 | E30: =C30 -> 4.2916667 | F30: =C30+Bm_Bf/24 -> 6.2916667 | G30: =MAX(D30,MIN(0,F30)) -> 2.2916667 | H30: =IF(Deck_Mode="uniform",Deck_Uni*(D30),Deck_Crown*ABS(D30)) -> -0.045833333 | I30: =IF(Deck_Mode="uniform",Deck_Uni*(E30),Deck_Crown*ABS(E30)) -> -0.085833333 | J30: =IF(Deck_Mode="uniform",Deck_Uni*(F30),Deck_Crown*ABS(F30)) -> -0.12583333 | K30: =IF(Deck_Mode="uniform",Deck_Uni*(G30),Deck_Crown*ABS(G30)) -> -0.045833333 | L30: =MIN(H30:K30) -> -0.12583333
A32: Layout checks
B33: Beam flanges inside the deck width | C33: =IF(AND(Bm1_FL>=Deck_YL-0.000000001,Bm2_FR<=Deck_YR+0.000000001),"PASS","FAIL") -> PASS
B34: Flanges do not overlap | C34: =IF(MIN(Bm_Gap1)>=Bm_Bf/12-0.000000001,"PASS","FAIL") -> PASS
B35: Deck mode implemented (crowned or uniform) | C35: =IF(OR(Deck_Mode="crowned",Deck_Mode="uniform"),"PASS","FAIL") -> PASS
B36: Profile mode implemented (brokeback or parabolic) | C36: =IF(OR(Prof_Mode="brokeback",Prof_Mode="parabolic"),"PASS","FAIL") -> PASS
B37: PI inside the profile | C37: =IF(AND(Prof_PISta>Prof_Sta0,Prof_PISta<Prof_Sta1),"PASS","FAIL") -> PASS

Sheet Profile & Deck Method
B1: Profile & Deck - Method | P1: Figure data
B2: Profile grade line, deck cross slope, beam offsets and haunch check points | P2: Live formulas that draw the charts on this tab. Do not edit; change the notebook CONFIG and rebuild.
B3: =IF(Inputs_Edited=0,"LIVE Charts, tables and the numbers quoted in this text are workbook formulas. Inputs match the notebook build (model "&Build_Model&", built "&Build_Time&").",Inputs_Edited&" INPUT(S) EDITED SINCE THE NOTEBOOK BUILD The charts and tables follow the edited inputs, which no longer match the geometry notebook (QC "&QC_Overall&"). Change the notebook CONFIG and rebuild.") -> LIVE Charts, tables and the numbers quoted in this text are workbook formulas. Inputs match the notebook build (model e9b41b8eaf, built 2026-10-19 12:13).
P4: Profile along the bridge
B5: 1. Profile grade line (PGL) | P5: Series / label text | Q5: x | R5: y | S5: error +
B6: ="The notebook profile mode is """&Prof_Mode&""". In brokeback mode the PGL is two straight tangents of nominal grade g that meet at the tangent intersection station. The PI elevation averages the two tangents projected to the PI, which preserves both end elevations:" -> The notebook profile mode is "brokeback". In brokeback mode the PGL is two straight tangents of nominal grade g that meet at the tangent intersection station. The PI elevation averages the two tangents projected to the PI, which preserves both end elevations: | P6: PGL | Q6: =Prof_Sta0+0/12*(Prof_PISta-Prof_Sta0) -> 1593.22 | R6: =IF(Prof_Mode="parabolic",Prof_Z0+Prof_G1*(($Q$6)-Prof_Sta0)+Prof_Kq*(($Q$6)-Prof_Sta0)^2,IF(($Q$6)<=Prof_PISta,Prof_Z0+Prof_G1*(($Q$6)-Prof_Sta0),Prof_PIZ+Prof_G2*(($Q$6)-Prof_PISta))) -> 47.661
Q7: =Prof_Sta0+1/12*(Prof_PISta-Prof_Sta0) -> 1602.1658 | R7: =IF(Prof_Mode="parabolic",Prof_Z0+Prof_G1*(($Q$7)-Prof_Sta0)+Prof_Kq*(($Q$7)-Prof_Sta0)^2,IF(($Q$7)<=Prof_PISta,Prof_Z0+Prof_G1*(($Q$7)-Prof_Sta0),Prof_PIZ+Prof_G2*(($Q$7)-Prof_PISta))) -> 47.705719
Q8: =Prof_Sta0+2/12*(Prof_PISta-Prof_Sta0) -> 1611.1117 | R8: =IF(Prof_Mode="parabolic",Prof_Z0+Prof_G1*(($Q$8)-Prof_Sta0)+Prof_Kq*(($Q$8)-Prof_Sta0)^2,IF(($Q$8)<=Prof_PISta,Prof_Z0+Prof_G1*(($Q$8)-Prof_Sta0),Prof_PIZ+Prof_G2*(($Q$8)-Prof_PISta))) -> 47.750438
Q9: =Prof_Sta0+3/12*(Prof_PISta-Prof_Sta0) -> 1620.0575 | R9: =IF(Prof_Mode="parabolic",Prof_Z0+Prof_G1*(($Q$9)-Prof_Sta0)+Prof_Kq*(($Q$9)-Prof_Sta0)^2,IF(($Q$9)<=Prof_PISta,Prof_Z0+Prof_G1*(($Q$9)-Prof_Sta0),Prof_PIZ+Prof_G2*(($Q$9)-Prof_PISta))) -> 47.795156
Q10: =Prof_Sta0+4/12*(Prof_PISta-Prof_Sta0) -> 1629.0033 | R10: =IF(Prof_Mode="parabolic",Prof_Z0+Prof_G1*(($Q$10)-Prof_Sta0)+Prof_Kq*(($Q$10)-Prof_Sta0)^2,IF(($Q$10)<=Prof_PISta,Prof_Z0+Prof_G1*(($Q$10)-Prof_Sta0),Prof_PIZ+Prof_G2*(($Q$10)-Prof_PISta))) -> 47.839875
Q11: =Prof_Sta0+5/12*(Prof_PISta-Prof_Sta0) -> 1637.9492 | R11: =IF(Prof_Mode="parabolic",Prof_Z0+Prof_G1*(($Q$11)-Prof_Sta0)+Prof_Kq*(($Q$11)-Prof_Sta0)^2,IF(($Q$11)<=Prof_PISta,Prof_Z0+Prof_G1*(($Q$11)-Prof_Sta0),Prof_PIZ+Prof_G2*(($Q$11)-Prof_PISta))) -> 47.884594
Q12: =Prof_Sta0+6/12*(Prof_PISta-Prof_Sta0) -> 1646.895 | R12: =IF(Prof_Mode="parabolic",Prof_Z0+Prof_G1*(($Q$12)-Prof_Sta0)+Prof_Kq*(($Q$12)-Prof_Sta0)^2,IF(($Q$12)<=Prof_PISta,Prof_Z0+Prof_G1*(($Q$12)-Prof_Sta0),Prof_PIZ+Prof_G2*(($Q$12)-Prof_PISta))) -> 47.929313
Q13: =Prof_Sta0+7/12*(Prof_PISta-Prof_Sta0) -> 1655.8408 | R13: =IF(Prof_Mode="parabolic",Prof_Z0+Prof_G1*(($Q$13)-Prof_Sta0)+Prof_Kq*(($Q$13)-Prof_Sta0)^2,IF(($Q$13)<=Prof_PISta,Prof_Z0+Prof_G1*(($Q$13)-Prof_Sta0),Prof_PIZ+Prof_G2*(($Q$13)-Prof_PISta))) -> 47.974031
Q14: =Prof_Sta0+8/12*(Prof_PISta-Prof_Sta0) -> 1664.7867 | R14: =IF(Prof_Mode="parabolic",Prof_Z0+Prof_G1*(($Q$14)-Prof_Sta0)+Prof_Kq*(($Q$14)-Prof_Sta0)^2,IF(($Q$14)<=Prof_PISta,Prof_Z0+Prof_G1*(($Q$14)-Prof_Sta0),Prof_PIZ+Prof_G2*(($Q$14)-Prof_PISta))) -> 48.01875
Q15: =Prof_Sta0+9/12*(Prof_PISta-Prof_Sta0) -> 1673.7325 | R15: =IF(Prof_Mode="parabolic",Prof_Z0+Prof_G1*(($Q$15)-Prof_Sta0)+Prof_Kq*(($Q$15)-Prof_Sta0)^2,IF(($Q$15)<=Prof_PISta,Prof_Z0+Prof_G1*(($Q$15)-Prof_Sta0),Prof_PIZ+Prof_G2*(($Q$15)-Prof_PISta))) -> 48.063469
B16: ="Current values: g1 = "&TEXT(Prof_G1*100,"+0.000000;-0.000000")&"%, g2 = "&TEXT(Prof_G2*100,"+0.000000;-0.000000")&"%, z_PI = "&IF(Prof_Mode="brokeback",TEXT(Prof_PIZ,"0.000000")&" ft","n/a (parabolic)")&" at "&TEXT(INT(ROUND(Prof_PISta*100,0)/10000),"0")&"+"&TEXT(MOD(ROUND(Prof_PISta*100,0),10000)/100,"00.00")&"." -> Current values: g1 = +0.499884%, g2 = -0.500119%, z_PI = 48.197625 ft at 17+00.57. | Q16: =Prof_Sta0+10/12*(Prof_PISta-Prof_Sta0) -> 1682.6783 | R16: =IF(Prof_Mode="parabolic",Prof_Z0+Prof_G1*(($Q$16)-Prof_Sta0)+Prof_Kq*(($Q$16)-Prof_Sta0)^2,IF(($Q$16)<=Prof_PISta,Prof_Z0+Prof_G1*(($Q$16)-Prof_Sta0),Prof_PIZ+Prof_G2*(($Q$16)-Prof_PISta))) -> 48.108187
B17: Parabolic mode (also in the notebook) keeps both end elevations and the entered grade change Δg, with x = s - s0 and L = s1 - s0: | Q17: =Prof_Sta0+11/12*(Prof_PISta-Prof_Sta0) -> 1691.6242 | R17: =IF(Prof_Mode="parabolic",Prof_Z0+Prof_G1*(($Q$17)-Prof_Sta0)+Prof_Kq*(($Q$17)-Prof_Sta0)^2,IF(($Q$17)<=Prof_PISta,Prof_Z0+Prof_G1*(($Q$17)-Prof_Sta0),Prof_PIZ+Prof_G2*(($Q$17)-Prof_PISta))) -> 48.152906
Q18: =Prof_Sta0+12/12*(Prof_PISta-Prof_Sta0) -> 1700.57 | R18: =IF(Prof_Mode="parabolic",Prof_Z0+Prof_G1*(($Q$18)-Prof_Sta0)+Prof_Kq*(($Q$18)-Prof_Sta0)^2,IF(($Q$18)<=Prof_PISta,Prof_Z0+Prof_G1*(($Q$18)-Prof_Sta0),Prof_PIZ+Prof_G2*(($Q$18)-Prof_PISta))) -> 48.197625
Q19: =Prof_PISta+1/12*(Prof_Sta1-Prof_PISta) -> 1709.3117 | R19: =IF(Prof_Mode="parabolic",Prof_Z0+Prof_G1*(($Q$19)-Prof_Sta0)+Prof_Kq*(($Q$19)-Prof_Sta0)^2,IF(($Q$19)<=Prof_PISta,Prof_Z0+Prof_G1*(($Q$19)-Prof_Sta0),Prof_PIZ+Prof_G2*(($Q$19)-Prof_PISta))) -> 48.153906
Q20: =Prof_PISta+2/12*(Prof_Sta1-Prof_PISta) -> 1718.0533 | R20: =IF(Prof_Mode="parabolic",Prof_Z0+Prof_G1*(($Q$20)-Prof_Sta0)+Prof_Kq*(($Q$20)-Prof_Sta0)^2,IF(($Q$20)<=Prof_PISta,Prof_Z0+Prof_G1*(($Q$20)-Prof_Sta0),Prof_PIZ+Prof_G2*(($Q$20)-Prof_PISta))) -> 48.110188
Q21: =Prof_PISta+3/12*(Prof_Sta1-Prof_PISta) -> 1726.795 | R21: =IF(Prof_Mode="parabolic",Prof_Z0+Prof_G1*(($Q$21)-Prof_Sta0)+Prof_Kq*(($Q$21)-Prof_Sta0)^2,IF(($Q$21)<=Prof_PISta,Prof_Z0+Prof_G1*(($Q$21)-Prof_Sta0),Prof_PIZ+Prof_G2*(($Q$21)-Prof_PISta))) -> 48.066469
Q22: =Prof_PISta+4/12*(Prof_Sta1-Prof_PISta) -> 1735.5367 | R22: =IF(Prof_Mode="parabolic",Prof_Z0+Prof_G1*(($Q$22)-Prof_Sta0)+Prof_Kq*(($Q$22)-Prof_Sta0)^2,IF(($Q$22)<=Prof_PISta,Prof_Z0+Prof_G1*(($Q$22)-Prof_Sta0),Prof_PIZ+Prof_G2*(($Q$22)-Prof_PISta))) -> 48.02275
Q23: =Prof_PISta+5/12*(Prof_Sta1-Prof_PISta) -> 1744.2783 | R23: =IF(Prof_Mode="parabolic",Prof_Z0+Prof_G1*(($Q$23)-Prof_Sta0)+Prof_Kq*(($Q$23)-Prof_Sta0)^2,IF(($Q$23)<=Prof_PISta,Prof_Z0+Prof_G1*(($Q$23)-Prof_Sta0),Prof_PIZ+Prof_G2*(($Q$23)-Prof_PISta))) -> 47.979031
Q24: =Prof_PISta+6/12*(Prof_Sta1-Prof_PISta) -> 1753.02 | R24: =IF(Prof_Mode="parabolic",Prof_Z0+Prof_G1*(($Q$24)-Prof_Sta0)+Prof_Kq*(($Q$24)-Prof_Sta0)^2,IF(($Q$24)<=Prof_PISta,Prof_Z0+Prof_G1*(($Q$24)-Prof_Sta0),Prof_PIZ+Prof_G2*(($Q$24)-Prof_PISta))) -> 47.935313
Q25: =Prof_PISta+7/12*(Prof_Sta1-Prof_PISta) -> 1761.7617 | R25: =IF(Prof_Mode="parabolic",Prof_Z0+Prof_G1*(($Q$25)-Prof_Sta0)+Prof_Kq*(($Q$25)-Prof_Sta0)^2,IF(($Q$25)<=Prof_PISta,Prof_Z0+Prof_G1*(($Q$25)-Prof_Sta0),Prof_PIZ+Prof_G2*(($Q$25)-Prof_PISta))) -> 47.891594
Q26: =Prof_PISta+8/12*(Prof_Sta1-Prof_PISta) -> 1770.5033 | R26: =IF(Prof_Mode="parabolic",Prof_Z0+Prof_G1*(($Q$26)-Prof_Sta0)+Prof_Kq*(($Q$26)-Prof_Sta0)^2,IF(($Q$26)<=Prof_PISta,Prof_Z0+Prof_G1*(($Q$26)-Prof_Sta0),Prof_PIZ+Prof_G2*(($Q$26)-Prof_PISta))) -> 47.847875
Q27: =Prof_PISta+9/12*(Prof_Sta1-Prof_PISta) -> 1779.245 | R27: =IF(Prof_Mode="parabolic",Prof_Z0+Prof_G1*(($Q$27)-Prof_Sta0)+Prof_Kq*(($Q$27)-Prof_Sta0)^2,IF(($Q$27)<=Prof_PISta,Prof_Z0+Prof_G1*(($Q$27)-Prof_Sta0),Prof_PIZ+Prof_G2*(($Q$27)-Prof_PISta))) -> 47.804156
Q28: =Prof_PISta+10/12*(Prof_Sta1-Prof_PISta) -> 1787.9867 | R28: =IF(Prof_Mode="parabolic",Prof_Z0+Prof_G1*(($Q$28)-Prof_Sta0)+Prof_Kq*(($Q$28)-Prof_Sta0)^2,IF(($Q$28)<=Prof_PISta,Prof_Z0+Prof_G1*(($Q$28)-Prof_Sta0),Prof_PIZ+Prof_G2*(($Q$28)-Prof_PISta))) -> 47.760438
Q29: =Prof_PISta+11/12*(Prof_Sta1-Prof_PISta) -> 1796.7283 | R29: =IF(Prof_Mode="parabolic",Prof_Z0+Prof_G1*(($Q$29)-Prof_Sta0)+Prof_Kq*(($Q$29)-Prof_Sta0)^2,IF(($Q$29)<=Prof_PISta,Prof_Z0+Prof_G1*(($Q$29)-Prof_Sta0),Prof_PIZ+Prof_G2*(($Q$29)-Prof_PISta))) -> 47.716719
Q30: =Prof_PISta+12/12*(Prof_Sta1-Prof_PISta) -> 1805.47 | R30: =IF(Prof_Mode="parabolic",Prof_Z0+Prof_G1*(($Q$30)-Prof_Sta0)+Prof_Kq*(($Q$30)-Prof_Sta0)^2,IF(($Q$30)<=Prof_PISta,Prof_Z0+Prof_G1*(($Q$30)-Prof_Sta0),Prof_PIZ+Prof_G2*(($Q$30)-Prof_PISta))) -> 47.673
P32: Lowest PGL less 0.25 ft | Q32: =MIN(R6:R30)-0.25 -> 47.411
P33: Highest PGL plus 0.1 ft | Q33: =MAX(R6:R30)+0.1 -> 48.297625
P34: Span datums | Q34: =Sp1_Sta0 -> 1593.22 | R34: =$Q$32 -> 47.411
Q35: =Sp1_Sta0 -> 1593.22 | R35: =$Q$33 -> 48.297625
Q37: =Sp1_Sta1 -> 1700.57 | R37: =$Q$32 -> 47.411
Q38: =Sp1_Sta1 -> 1700.57 | R38: =$Q$33 -> 48.297625
B39: Figure 1. Profile along the bridge, drawn from the PGL formulas (vertical scale exaggerated by the chart shape).
Q40: =Sp2_Sta1 -> 1805.47 | R40: =$Q$32 -> 47.411
B41: 2. Deck surface | Q41: =Sp2_Sta1 -> 1805.47 | R41: =$Q$33 -> 48.297625
B42: The deck top at offset y adds a cross-slope term to the PGL. Crowned mode slopes both sides away from the PGL; uniform mode applies one slope across the deck. (The notebook transition mode is not implemented in this workbook; QC fails if it is selected.)
...

Sheet Beam Geometry
A1: Beam Geometry | O1: Project | P1: =""&TB_Project -> D2 I-95 Pedestrian Bridge
A2: Physical beam ends, bearings, deck limits, bearing chords and Table of Beam Variables dimensions | O2: Job No. | P2: =""&TB_JobNo
O3: Calc. by / date | P3: =TB_CalcBy&" "&TB_CalcDate
O4: Check. by / date | P4: =TB_CheckBy&" "&TB_CheckDate
A6: Span layout (stations in ft)
B7: Span | C7: Datum start | D7: Datum end | E7: Start support | F7: End support | G7: Beam start | H7: Beam end | I7: CL brg A (start) | J7: CL brg B (end) | K7: Deck start | L7: Deck end | M7: Beam length | N7: Brg span Lb | O7: Brg midpoint | P7: PGL at A | Q7: PGL at B | R7: Chord grade | S7: Layout check | T7: Mathcad L.beam | U7: Beam length - Mathcad
B8: 1 | C8: =Sp1_Sta0 -> 1593.22 | D8: =Sp1_Sta1 -> 1700.57 | E8: End Bent 1 | F8: Pier | G8: =C8+Phys_EndClr/12 -> 1593.47 | H8: =D8-Phys_PierGap/24 -> 1700.445 | I8: =G8+Phys_Setback/12 -> 1594.22 | J8: =H8-Phys_Setback/12 -> 1699.695 | K8: =C8+Phys_DeckClr/12 -> 1593.47 | L8: =D8 -> 1700.57 | M8: =H8-G8 -> 106.975 | N8: =J8-I8 -> 105.475 | O8: =(I8+J8)/2 -> 1646.9575 | P8: =IF(Prof_Mode="parabolic",Prof_Z0+Prof_G1*((I8)-Prof_Sta0)+Prof_Kq*((I8)-Prof_Sta0)^2,IF((I8)<=Prof_PISta,Prof_Z0+Prof_G1*((I8)-Prof_Sta0),Prof_PIZ+Prof_G2*((I8)-Prof_PISta))) -> 47.665999 | Q8: =IF(Prof_Mode="parabolic",Prof_Z0+Prof_G1*((J8)-Prof_Sta0)+Prof_Kq*((J8)-Prof_Sta0)^2,IF((J8)<=Prof_PISta,Prof_Z0+Prof_G1*((J8)-Prof_Sta0),Prof_PIZ+Prof_G2*((J8)-Prof_PISta))) -> 48.193251 | R8: =(Q8-P8)/N8 -> 0.0049988356 | S8: =IF(AND(C8<=G8,G8<I8,I8<J8,J8<H8,H8<=D8,K8<L8),"PASS","FAIL") -> PASS | T8: =MC1_Lbeam -> 106.975 | U8: =M8-T8 -> 0
B9: 2 | C9: =Sp2_Sta0 -> 1700.57 | D9: =Sp2_Sta1 -> 1805.47 | E9: Pier | F9: End Bent 2 | G9: =C9+Phys_PierGap/24 -> 1700.695 | H9: =D9-Phys_EndClr/12 -> 1805.22 | I9: =G9+Phys_Setback/12 -> 1701.445 | J9: =H9-Phys_Setback/12 -> 1804.47 | K9: =C9 -> 1700.57 | L9: =D9-Phys_DeckClr/12 -> 1805.22 | M9: =H9-G9 -> 104.525 | N9: =J9-I9 -> 103.025 | O9: =(I9+J9)/2 -> 1752.9575 | P9: =IF(Prof_Mode="parabolic",Prof_Z0+Prof_G1*((I9)-Prof_Sta0)+Prof_Kq*((I9)-Prof_Sta0)^2,IF((I9)<=Prof_PISta,Prof_Z0+Prof_G1*((I9)-Prof_Sta0),Prof_PIZ+Prof_G2*((I9)-Prof_PISta))) -> 48.193249 | Q9: =IF(Prof_Mode="parabolic",Prof_Z0+Prof_G1*((J9)-Prof_Sta0)+Prof_Kq*((J9)-Prof_Sta0)^2,IF((J9)<=Prof_PISta,Prof_Z0+Prof_G1*((J9)-Prof_Sta0),Prof_PIZ+Prof_G2*((J9)-Prof_PISta))) -> 47.678001 | R9: =(Q9-P9)/N9 -> -0.0050011916 | S9: =IF(AND(C9<=G9,G9<I9,I9<J9,J9<H9,H9<=D9,K9<L9),"PASS","FAIL") -> PASS | T9: =MC2_Lbeam -> 104.525 | U9: =M9-T9 -> 0
A11: Beam dimensions for the Table of Beam Variables (template method, notebook geometry)
B12: Beam | C12: Span | D12: Offset (ft) | E12: Raise (in) | F12: Horizontal length (ft) | G12: Sloped length Ls (ft) | H12: Skew (deg) | I12: Angle phi End 1 | J12: Angle phi End 2 | K12: Dim J (in) | L12: Dim K1 (in) | M12: Dim K2 (in) | N12: Dim P (in) | O12: End elev. cond. | P12: Prestress P (kip) | Q12: Creep factor C1 | R12: Shortening R (in) | S12: Dim L incl. R (ft) | T12: Dim L ft | U12: Dim L in
B13: 1-1 | C13: 1 | D13: =Bm1_Off -> -4.2916667 | E13: =Bm1_Raise -> 0 | F13: =Sp1_LBeam -> 106.975 | G13: =F13*SQRT(1+Sp1_Gc^2) -> 106.97634 | H13: =MC1_Skew -> 0 | I13: =90-H13 -> 90 | J13: =90-H13 -> 90 | K13: =Phys_Setback -> 9 | L13: =(Sp1_BrgA-Sp1_Sta0)*12 -> 12 | M13: =(Sp1_Sta1-Sp1_BrgB)*12 -> 10.5 | N13: =IF(ABS(Sp1_Gc*Bm_D*12)<Des_DimP,0,-Sp1_Gc*Bm_D*12) -> 0 | O13: =IF(N13<0,2,IF(N13>0,3,1)) -> 1 | P13: =MC1_NStr*MC1_Pj+MC1_NTop*MC1_PTop -> 1753.7575 | Q13: =1+MC1_Psi -> 1.9583197 | R13: =Q13*P13*G13*12/(MC1_Eci*Bm_Area)+ABS(MC1_Esh)*G13*12 -> 1.5229584 | S13: =G13+R13/12 -> 107.10325 | T13: =ROUNDDOWN(S13,0) -> 107 | U13: =(S13-T13)*12 -> 1.238997
B14: 1-2 | C14: 1 | D14: =Bm2_Off -> 4.2916667 | E14: =Bm2_Raise -> 0 | F14: =Sp1_LBeam -> 106.975 | G14: =F14*SQRT(1+Sp1_Gc^2) -> 106.97634 | H14: =MC1_Skew -> 0 | I14: =90-H14 -> 90 | J14: =90-H14 -> 90 | K14: =Phys_Setback -> 9 | L14: =(Sp1_BrgA-Sp1_Sta0)*12 -> 12 | M14: =(Sp1_Sta1-Sp1_BrgB)*12 -> 10.5 | N14: =IF(ABS(Sp1_Gc*Bm_D*12)<Des_DimP,0,-Sp1_Gc*Bm_D*12) -> 0 | O14: =IF(N14<0,2,IF(N14>0,3,1)) -> 1 | P14: =MC1_NStr*MC1_Pj+MC1_NTop*MC1_PTop -> 1753.7575 | Q14: =1+MC1_Psi -> 1.9583197 | R14: =Q14*P14*G14*12/(MC1_Eci*Bm_Area)+ABS(MC1_Esh)*G14*12 -> 1.5229584 | S14: =G14+R14/12 -> 107.10325 | T14: =ROUNDDOWN(S14,0) -> 107 | U14: =(S14-T14)*12 -> 1.238997
B15: 2-1 | C15: 2 | D15: =Bm1_Off -> -4.2916667 | E15: =Bm1_Raise -> 0 | F15: =Sp2_LBeam -> 104.525 | G15: =F15*SQRT(1+Sp2_Gc^2) -> 104.52631 | H15: =MC2_Skew -> 0 | I15: =90-H15 -> 90 | J15: =90-H15 -> 90 | K15: =Phys_Setback -> 9 | L15: =(Sp2_BrgA-Sp2_Sta0)*12 -> 10.5 | M15: =(Sp2_Sta1-Sp2_BrgB)*12 -> 12 | N15: =IF(ABS(Sp2_Gc*Bm_D*12)<Des_DimP,0,-Sp2_Gc*Bm_D*12) -> 0 | O15: =IF(N15<0,2,IF(N15>0,3,1)) -> 1 | P15: =MC2_NStr*MC2_Pj+MC2_NTop*MC2_PTop -> 1753.7575 | Q15: =1+MC2_Psi -> 1.9583197 | R15: =Q15*P15*G15*12/(MC2_Eci*Bm_Area)+ABS(MC2_Esh)*G15*12 -> 1.4880787 | S15: =G15+R15/12 -> 104.65031 | T15: =ROUNDDOWN(S15,0) -> 104 | U15: =(S15-T15)*12 -> 7.8037649
B16: 2-2 | C16: 2 | D16: =Bm2_Off -> 4.2916667 | E16: =Bm2_Raise -> 0 | F16: =Sp2_LBeam -> 104.525 | G16: =F16*SQRT(1+Sp2_Gc^2) -> 104.52631 | H16: =MC2_Skew -> 0 | I16: =90-H16 -> 90 | J16: =90-H16 -> 90 | K16: =Phys_Setback -> 9 | L16: =(Sp2_BrgA-Sp2_Sta0)*12 -> 10.5 | M16: =(Sp2_Sta1-Sp2_BrgB)*12 -> 12 | N16: =IF(ABS(Sp2_Gc*Bm_D*12)<Des_DimP,0,-Sp2_Gc*Bm_D*12) -> 0 | O16: =IF(N16<0,2,IF(N16>0,3,1)) -> 1 | P16: =MC2_NStr*MC2_Pj+MC2_NTop*MC2_PTop -> 1753.7575 | Q16: =1+MC2_Psi -> 1.9583197 | R16: =Q16*P16*G16*12/(MC2_Eci*Bm_Area)+ABS(MC2_Esh)*G16*12 -> 1.4880787 | S16: =G16+R16/12 -> 104.65031 | T16: =ROUNDDOWN(S16,0) -> 104 | U16: =(S16-T16)*12 -> 7.8037649
B18: Dim L follows the BCC template (sloped beam length + shortening R). Confirm against the current FDOT instructions for the Table of Beam Variables before issue; the sloped length without R is column G.

Sheet Beam Geometry Method
B1: Beam Geometry - Method
B2: Physical beam ends, bearings and the Table of Beam Variables dimensions
B3: =IF(Inputs_Edited=0,"LIVE Charts, tables and the numbers quoted in this text are workbook formulas. Inputs match the notebook build (model "&Build_Model&", built "&Build_Time&").",Inputs_Edited&" INPUT(S) EDITED SINCE THE NOTEBOOK BUILD The charts and tables follow the edited inputs, which no longer match the geometry notebook (QC "&QC_Overall&"). Change the notebook CONFIG and rebuild.") -> LIVE Charts, tables and the numbers quoted in this text are workbook formulas. Inputs match the notebook build (model e9b41b8eaf, built 2026-10-19 12:13).
B5: 1. Physical beam ends and bearings
B6: Spans run between datums: the front face of backwall (FFBW) at end bents and the pier centerline. Beams stop short of each datum by the beam-end clearance e at an end bent, or by half the pier gap g at the pier. Bearings sit a setback j inside each beam end. The deck stops a clearance cd inside each FFBW and is continuous over the pier:
B10: ="Current: e = "&TEXT(Phys_EndClr,"General")&" in, g = "&TEXT(Phys_PierGap,"General")&" in, j = "&TEXT(Phys_Setback,"General")&" in, cd = "&TEXT(Phys_DeckClr,"General")&" in. Span 1 bearings "&TEXT(INT(ROUND(Sp1_BrgA*100,0)/10000),"0")&"+"&TEXT(MOD(ROUND(Sp1_BrgA*100,0),10000)/100,"00.00")&" to "&TEXT(INT(ROUND(Sp1_BrgB*100,0)/10000),"0")&"+"&TEXT(MOD(ROUND(Sp1_BrgB*100,0),10000)/100,"00.00")&"; Span 2 bearings "&TEXT(INT(ROUND(Sp2_BrgA*100,0)/10000),"0")&"+"&TEXT(MOD(ROUND(Sp2_BrgA*100,0),10000)/100,"00.00")&" to "&TEXT(INT(ROUND(Sp2_BrgB*100,0)/10000),"0")&"+"&TEXT(MOD(ROUND(Sp2_BrgB*100,0),10000)/100,"00.00")&"." -> Current: e = 3 in, g = 3 in, j = 9 in, cd = 3 in. Span 1 bearings 15+94.22 to 16+99.70; Span 2 bearings 17+01.45 to 18+04.47.
B25: Figure 1. Beam-end, bearing and pier-joint dimensions (elevation, not to scale). Current values are in the table below.
B26: Symbol | C26: Meaning | H26: Workbook name / location | K26: Units / value
B27: e | C27: Beam end clearance to the FFBW | H27: Phys_EndClr | K27: =TEXT(Phys_EndClr,"General")&" in" -> 3 in
B28: J | C28: Bearing setback, beam end to CL bearing (Dim J) | H28: Phys_Setback | K28: =TEXT(Phys_Setback,"General")&" in" -> 9 in
B29: K1 = e + J | C29: FFBW to CL bearing at an end bent (Dim K1 / K2) | H29: Beam Geometry cols L, M | K29: =TEXT(Phys_EndClr+Phys_Setback,"General")&" in" -> 12 in
B30: g | C30: Pier beam gap, beam end to beam end | H30: Phys_PierGap | K30: =TEXT(Phys_PierGap,"General")&" in" -> 3 in
B31: K = g/2 + J | C31: CL pier to CL bearing | H31: Beam Geometry cols L, M | K31: =TEXT(Phys_PierGap/2+Phys_Setback,"General")&" in" -> 10.5 in
B34: 2. Bearing chord and sloped length
B38: The beam soffit chord between bearings is parallel to the PGL chord (the notebook drops all bearings by the same D; see Camber & Haunch). QC compares the horizontal beam length with the Mathcad L.beam.
B40: 3. Table of Beam Variables dimensions (BCC template method)
B47: Elastic plus time-dependent shortening R uses the template expression with the Mathcad prestress, creep and shrinkage values:
B54: Dim L adds R to the sloped length, exactly as the BCC template did. Confirm against the current FDOT Table of Beam Variables instructions before issue; the sloped length without R is shown in the Ls column.
B68: Figure 2. End-of-beam dimensions used in the Table of Beam Variables.
B69: Symbol | C69: Meaning | H69: Workbook name / location | K69: Units / value
B70: sa, sb | C70: Span datum stations (FFBW or CL pier) | H70: Sp1_Sta0, Sp1_Sta1 ... | K70: ft
B71: sA, sB | C71: Bearing stations | H71: Sp1_BrgA, Sp1_BrgB ... | K71: ft
B72: Lb, gc | C72: Bearing span and chord grade | H72: Sp1_Lb, Sp1_Gc ... | K72: ft, ft/ft
B73: P | C73: Total prestress force at jacking | H73: Beam Geometry col P | K73: kip
B74: Ag, Eci | C74: FIB-36 gross area; release modulus (Mathcad) | H74: Bm_Area, MC1_Eci | K74: in2, ksi

Sheet Camber & Haunch
A1: Camber & Haunch | L1: Project | M1: =""&TB_Project -> D2 I-95 Pedestrian Bridge
A2: Common support drop, build-up (Dims B, C, D) and minimum flange haunch | L2: Job No. | M2: =""&TB_JobNo
L3: Calc. by / date | M3: =TB_CalcBy&" "&TB_CalcDate
L4: Check. by / date | M4: =TB_CheckBy&" "&TB_CheckDate
A6: A. Haunch shape per span: h(t) = K - m t(1-t), with t = (s - brg A)/Lb
B7: Span | C7: Camber C (in) | D7: Lb (ft) | E7: t at beam start | F7: t at beam end | G7: m (ft) | H7: max of m t(1-t) on beam | I7: Mathcad NetCamber (in) | J7: C - Mathcad (in)
B8: 1 | C8: =Sp1_C -> 0.12459274 | D8: =Sp1_Lb -> 105.475 | E8: =(Sp1_Bm0-Sp1_BrgA)/Sp1_Lb -> -0.0071106897 | F8: =(Sp1_Bm1-Sp1_BrgA)/Sp1_Lb -> 1.0071107 | G8: =Prof_Kq*Sp1_Lb^2+Sp1_C/3 -> 0.041530915 | H8: =MAX(G8/4,G8*E8*(1-E8),G8*F8*(1-F8)) -> 0.010382729 | I8: =MC1_Net -> 0.12459274 | J8: =C8-I8 -> 0
B9: 2 | C9: =Sp2_C -> 0.56717146 | D9: =Sp2_Lb -> 103.025 | E9: =(Sp2_Bm0-Sp2_BrgA)/Sp2_Lb -> -0.0072797865 | F9: =(Sp2_Bm1-Sp2_BrgA)/Sp2_Lb -> 1.0072798 | G9: =Prof_Kq*Sp2_Lb^2+Sp2_C/3 -> 0.18905715 | H9: =MAX(G9/4,G9*E9*(1-E9),G9*F9*(1-F9)) -> 0.047264289 | I9: =MC2_Net -> 0.56717146 | J9: =C9-I9 -> 0
A11: B. Minimum uncorrected haunch per beam and the common support drop D
B12: Beam | C12: delta min (ft) | D12: Raise (in) | E12: Min haunch with D = 0 (ft) | F12: Min flange haunch (in)
B13: 1-1 | C13: =Bm1_dMin -> -0.12583333 | D13: =Bm1_Raise -> 0 | E13: =C13-Deck_T-D13/12-Bm_D-Sp1_W -> -3.6362161 | F13: =(E13+Sup_Drop)*12 -> 0.94257872
B14: 1-2 | C14: =Bm2_dMin -> -0.12583333 | D14: =Bm2_Raise -> 0 | E14: =C14-Deck_T-D14/12-Bm_D-Sp1_W -> -3.6362161 | F14: =(E14+Sup_Drop)*12 -> 0.94257872
B15: 2-1 | C15: =Bm1_dMin -> -0.12583333 | D15: =Bm1_Raise -> 0 | E15: =C15-Deck_T-D15/12-Bm_D-Sp2_W -> -3.6730976 | F15: =(E15+Sup_Drop)*12 -> 0.5
B16: 2-2 | C16: =Bm2_dMin -> -0.12583333 | D16: =Bm2_Raise -> 0 | E16: =C16-Deck_T-D16/12-Bm_D-Sp2_W -> -3.6730976 | F16: =(E16+Sup_Drop)*12 -> 0.5
B18: Common support drop D (ft) | E18: =Bm_Hmin/12-MIN(E13:E16) -> 3.7147643 | G18: D = h_min,req - min over every beam and flange point of the haunch with D = 0
B19: Minimum flange haunch, whole bridge (in) | E19: =MIN(F13:F16) -> 0.5 | F19: =IF(E19>=Bm_Hmin-0.00000001,"PASS","FAIL") -> PASS
A21: C. Haunch over each beam at the bearings and midspan
B22: Beam | C22: Location | D22: Station s (ft) | E22: t | F22: PGL (ft) | G22: Chord (ft) | H22: Camber (ft) | I22: Beam bottom (ft) | J22: Beam top (ft) | K22: Deck @ CL beam (ft) | L22: Haunch @ CL (in) | M22: Min flange haunch (in)
B23: 1-1 | C23: Begin brg | D23: =Sp1_BrgA -> 1594.22 | E23: =(D23-Sp1_BrgA)/Sp1_Lb -> 0 | F23: =IF(Prof_Mode="parabolic",Prof_Z0+Prof_G1*((D23)-Prof_Sta0)+Prof_Kq*((D23)-Prof_Sta0)^2,IF((D23)<=Prof_PISta,Prof_Z0+Prof_G1*((D23)-Prof_Sta0),Prof_PIZ+Prof_G2*((D23)-Prof_PISta))) -> 47.665999 | G23: =Sp1_ZA+(Sp1_ZB-Sp1_ZA)*E23 -> 47.665999 | H23: =Sp1_C/3*E23*(1-E23) -> 0 | I23: =G23-Sup_Drop+H23+Bm1_Raise/12 -> 43.951235 | J23: =I23+Bm_D -> 46.951235 | K23: =F23+Bm1_dCL -> 47.580166 | L23: =(K23-Deck_T-J23)*12 -> 1.5471715 | M23: =(F23+Bm1_dMin-Deck_T-J23)*12 -> 1.0671715
B24: 1-1 | C24: Midspan | D24: =Sp1_Mid -> 1646.9575 | E24: =(D24-Sp1_BrgA)/Sp1_Lb -> 0.5 | F24: =IF(Prof_Mode="parabolic",Prof_Z0+Prof_G1*((D24)-Prof_Sta0)+Prof_Kq*((D24)-Prof_Sta0)^2,IF((D24)<=Prof_PISta,Prof_Z0+Prof_G1*((D24)-Prof_Sta0),Prof_PIZ+Prof_G2*((D24)-Prof_PISta))) -> 47.929625 | G24: =Sp1_ZA+(Sp1_ZB-Sp1_ZA)*E24 -> 47.929625 | H24: =Sp1_C/3*E24*(1-E24) -> 0.010382729 | I24: =G24-Sup_Drop+H24+Bm1_Raise/12 -> 44.225243 | J24: =I24+Bm_D -> 47.225243 | K24: =F24+Bm1_dCL -> 47.843792 | L24: =(K24-Deck_T-J24)*12 -> 1.4225787 | M24: =(F24+Bm1_dMin-Deck_T-J24)*12 -> 0.94257872
B25: 1-1 | C25: End brg | D25: =Sp1_BrgB -> 1699.695 | E25: =(D25-Sp1_BrgA)/Sp1_Lb -> 1 | F25: =IF(Prof_Mode="parabolic",Prof_Z0+Prof_G1*((D25)-Prof_Sta0)+Prof_Kq*((D25)-Prof_Sta0)^2,IF((D25)<=Prof_PISta,Prof_Z0+Prof_G1*((D25)-Prof_Sta0),Prof_PIZ+Prof_G2*((D25)-Prof_PISta))) -> 48.193251 | G25: =Sp1_ZA+(Sp1_ZB-Sp1_ZA)*E25 -> 48.193251 | H25: =Sp1_C/3*E25*(1-E25) -> 0 | I25: =G25-Sup_Drop+H25+Bm1_Raise/12 -> 44.478487 | J25: =I25+Bm_D -> 47.478487 | K25: =F25+Bm1_dCL -> 48.107418 | L25: =(K25-Deck_T-J25)*12 -> 1.5471715 | M25: =(F25+Bm1_dMin-Deck_T-J25)*12 -> 1.0671715
B26: 1-2 | C26: Begin brg | D26: =Sp1_BrgA -> 1594.22 | E26: =(D26-Sp1_BrgA)/Sp1_Lb -> 0 | F26: =IF(Prof_Mode="parabolic",Prof_Z0+Prof_G1*((D26)-Prof_Sta0)+Prof_Kq*((D26)-Prof_Sta0)^2,IF((D26)<=Prof_PISta,Prof_Z0+Prof_G1*((D26)-Prof_Sta0),Prof_PIZ+Prof_G2*((D26)-Prof_PISta))) -> 47.665999 | G26: =Sp1_ZA+(Sp1_ZB-Sp1_ZA)*E26 -> 47.665999 | H26: =Sp1_C/3*E26*(1-E26) -> 0 | I26: =G26-Sup_Drop+H26+Bm2_Raise/12 -> 43.951235 | J26: =I26+Bm_D -> 46.951235 | K26: =F26+Bm2_dCL -> 47.580166 | L26: =(K26-Deck_T-J26)*12 -> 1.5471715 | M26: =(F26+Bm2_dMin-Deck_T-J26)*12 -> 1.0671715
B27: 1-2 | C27: Midspan | D27: =Sp1_Mid -> 1646.9575 | E27: =(D27-Sp1_BrgA)/Sp1_Lb -> 0.5 | F27: =IF(Prof_Mode="parabolic",Prof_Z0+Prof_G1*((D27)-Prof_Sta0)+Prof_Kq*((D27)-Prof_Sta0)^2,IF((D27)<=Prof_PISta,Prof_Z0+Prof_G1*((D27)-Prof_Sta0),Prof_PIZ+Prof_G2*((D27)-Prof_PISta))) -> 47.929625 | G27: =Sp1_ZA+(Sp1_ZB-Sp1_ZA)*E27 -> 47.929625 | H27: =Sp1_C/3*E27*(1-E27) -> 0.010382729 | I27: =G27-Sup_Drop+H27+Bm2_Raise/12 -> 44.225243 | J27: =I27+Bm_D -> 47.225243 | K27: =F27+Bm2_dCL -> 47.843792 | L27: =(K27-Deck_T-J27)*12 -> 1.4225787 | M27: =(F27+Bm2_dMin-Deck_T-J27)*12 -> 0.94257872
B28: 1-2 | C28: End brg | D28: =Sp1_BrgB -> 1699.695 | E28: =(D28-Sp1_BrgA)/Sp1_Lb -> 1 | F28: =IF(Prof_Mode="parabolic",Prof_Z0+Prof_G1*((D28)-Prof_Sta0)+Prof_Kq*((D28)-Prof_Sta0)^2,IF((D28)<=Prof_PISta,Prof_Z0+Prof_G1*((D28)-Prof_Sta0),Prof_PIZ+Prof_G2*((D28)-Prof_PISta))) -> 48.193251 | G28: =Sp1_ZA+(Sp1_ZB-Sp1_ZA)*E28 -> 48.193251 | H28: =Sp1_C/3*E28*(1-E28) -> 0 | I28: =G28-Sup_Drop+H28+Bm2_Raise/12 -> 44.478487 | J28: =I28+Bm_D -> 47.478487 | K28: =F28+Bm2_dCL -> 48.107418 | L28: =(K28-Deck_T-J28)*12 -> 1.5471715 | M28: =(F28+Bm2_dMin-Deck_T-J28)*12 -> 1.0671715
B29: 2-1 | C29: Begin brg | D29: =Sp2_BrgA -> 1701.445 | E29: =(D29-Sp2_BrgA)/Sp2_Lb -> 0 | F29: =IF(Prof_Mode="parabolic",Prof_Z0+Prof_G1*((D29)-Prof_Sta0)+Prof_Kq*((D29)-Prof_Sta0)^2,IF((D29)<=Prof_PISta,Prof_Z0+Prof_G1*((D29)-Prof_Sta0),Prof_PIZ+Prof_G2*((D29)-Prof_PISta))) -> 48.193249 | G29: =Sp2_ZA+(Sp2_ZB-Sp2_ZA)*E29 -> 48.193249 | H29: =Sp2_C/3*E29*(1-E29) -> 0 | I29: =G29-Sup_Drop+H29+Bm1_Raise/12 -> 44.478485 | J29: =I29+Bm_D -> 47.478485 | K29: =F29+Bm1_dCL -> 48.107416 | L29: =(K29-Deck_T-J29)*12 -> 1.5471715 | M29: =(F29+Bm1_dMin-Deck_T-J29)*12 -> 1.0671715
B30: 2-1 | C30: Midspan | D30: =Sp2_Mid -> 1752.9575 | E30: =(D30-Sp2_BrgA)/Sp2_Lb -> 0.5 | F30: =IF(Prof_Mode="parabolic",Prof_Z0+Prof_G1*((D30)-Prof_Sta0)+Prof_Kq*((D30)-Prof_Sta0)^2,IF((D30)<=Prof_PISta,Prof_Z0+Prof_G1*((D30)-Prof_Sta0),Prof_PIZ+Prof_G2*((D30)-Prof_PISta))) -> 47.935625 | G30: =Sp2_ZA+(Sp2_ZB-Sp2_ZA)*E30 -> 47.935625 | H30: =Sp2_C/3*E30*(1-E30) -> 0.047264289 | I30: =G30-Sup_Drop+H30+Bm1_Raise/12 -> 44.268125 | J30: =I30+Bm_D -> 47.268125 | K30: =F30+Bm1_dCL -> 47.849792 | L30: =(K30-Deck_T-J30)*12 -> 0.98 | M30: =(F30+Bm1_dMin-Deck_T-J30)*12 -> 0.5
B31: 2-1 | C31: End brg | D31: =Sp2_BrgB -> 1804.47 | E31: =(D31-Sp2_BrgA)/Sp2_Lb -> 1 | F31: =IF(Prof_Mode="parabolic",Prof_Z0+Prof_G1*((D31)-Prof_Sta0)+Prof_Kq*((D31)-Prof_Sta0)^2,IF((D31)<=Prof_PISta,Prof_Z0+Prof_G1*((D31)-Prof_Sta0),Prof_PIZ+Prof_G2*((D31)-Prof_PISta))) -> 47.678001 | G31: =Sp2_ZA+(Sp2_ZB-Sp2_ZA)*E31 -> 47.678001 | H31: =Sp2_C/3*E31*(1-E31) -> 0 | I31: =G31-Sup_Drop+H31+Bm1_Raise/12 -> 43.963237 | J31: =I31+Bm_D -> 46.963237 | K31: =F31+Bm1_dCL -> 47.592168 | L31: =(K31-Deck_T-J31)*12 -> 1.5471715 | M31: =(F31+Bm1_dMin-Deck_T-J31)*12 -> 1.0671715
B32: 2-2 | C32: Begin brg | D32: =Sp2_BrgA -> 1701.445 | E32: =(D32-Sp2_BrgA)/Sp2_Lb -> 0 | F32: =IF(Prof_Mode="parabolic",Prof_Z0+Prof_G1*((D32)-Prof_Sta0)+Prof_Kq*((D32)-Prof_Sta0)^2,IF((D32)<=Prof_PISta,Prof_Z0+Prof_G1*((D32)-Prof_Sta0),Prof_PIZ+Prof_G2*((D32)-Prof_PISta))) -> 48.193249 | G32: =Sp2_ZA+(Sp2_ZB-Sp2_ZA)*E32 -> 48.193249 | H32: =Sp2_C/3*E32*(1-E32) -> 0 | I32: =G32-Sup_Drop+H32+Bm2_Raise/12 -> 44.478485 | J32: =I32+Bm_D -> 47.478485 | K32: =F32+Bm2_dCL -> 48.107416 | L32: =(K32-Deck_T-J32)*12 -> 1.5471715 | M32: =(F32+Bm2_dMin-Deck_T-J32)*12 -> 1.0671715
B33: 2-2 | C33: Midspan | D33: =Sp2_Mid -> 1752.9575 | E33: =(D33-Sp2_BrgA)/Sp2_Lb -> 0.5 | F33: =IF(Prof_Mode="parabolic",Prof_Z0+Prof_G1*((D33)-Prof_Sta0)+Prof_Kq*((D33)-Prof_Sta0)^2,IF((D33)<=Prof_PISta,Prof_Z0+Prof_G1*((D33)-Prof_Sta0),Prof_PIZ+Prof_G2*((D33)-Prof_PISta))) -> 47.935625 | G33: =Sp2_ZA+(Sp2_ZB-Sp2_ZA)*E33 -> 47.935625 | H33: =Sp2_C/3*E33*(1-E33) -> 0.047264289 | I33: =G33-Sup_Drop+H33+Bm2_Raise/12 -> 44.268125 | J33: =I33+Bm_D -> 47.268125 | K33: =F33+Bm2_dCL -> 47.849792 | L33: =(K33-Deck_T-J33)*12 -> 0.98 | M33: =(F33+Bm2_dMin-Deck_T-J33)*12 -> 0.5
B34: 2-2 | C34: End brg | D34: =Sp2_BrgB -> 1804.47 | E34: =(D34-Sp2_BrgA)/Sp2_Lb -> 1 | F34: =IF(Prof_Mode="parabolic",Prof_Z0+Prof_G1*((D34)-Prof_Sta0)+Prof_Kq*((D34)-Prof_Sta0)^2,IF((D34)<=Prof_PISta,Prof_Z0+Prof_G1*((D34)-Prof_Sta0),Prof_PIZ+Prof_G2*((D34)-Prof_PISta))) -> 47.678001 | G34: =Sp2_ZA+(Sp2_ZB-Sp2_ZA)*E34 -> 47.678001 | H34: =Sp2_C/3*E34*(1-E34) -> 0 | I34: =G34-Sup_Drop+H34+Bm2_Raise/12 -> 43.963237 | J34: =I34+Bm_D -> 46.963237 | K34: =F34+Bm2_dCL -> 47.592168 | L34: =(K34-Deck_T-J34)*12 -> 1.5471715 | M34: =(F34+Bm2_dMin-Deck_T-J34)*12 -> 1.0671715
A36: D. Build-up summary (FDOT Build-Up & Deflection table)
B37: Beam | C37: Dim B begin (in) | D37: Dim C CL span (in) | E37: Dim D end (in) | F37: Mid-ordinate R (in) | G37: Net camber C (in) | H37: Build-up case
B38: 1-1 | C38: =L23 -> 1.5471715 | D38: =L24 -> 1.4225787 | E38: =L25 -> 1.5471715 | F38: =(K24-(K23+K25)/2)*12 -> 0 | G38: =Sp1_C -> 0.12459274 | H38: =IF(ROUND(F38,6)<0,"Case 2",IF(ROUND(F38,6)>G38,"Case 4",IF(ROUND(F38,6)>0,"Case 3","Case 1"))) -> Case 1
B39: 1-2 | C39: =L26 -> 1.5471715 | D39: =L27 -> 1.4225787 | E39: =L28 -> 1.5471715 | F39: =(K27-(K26+K28)/2)*12 -> 0 | G39: =Sp1_C -> 0.12459274 | H39: =IF(ROUND(F39,6)<0,"Case 2",IF(ROUND(F39,6)>G39,"Case 4",IF(ROUND(F39,6)>0,"Case 3","Case 1"))) -> Case 1
B40: 2-1 | C40: =L29 -> 1.5471715 | D40: =L30 -> 0.98 | E40: =L31 -> 1.5471715 | F40: =(K30-(K29+K31)/2)*12 -> 8.5265128e-14 | G40: =Sp2_C -> 0.56717146 | H40: =IF(ROUND(F40,6)<0,"Case 2",IF(ROUND(F40,6)>G40,"Case 4",IF(ROUND(F40,6)>0,"Case 3","Case 1"))) -> Case 1
B41: 2-2 | C41: =L32 -> 1.5471715 | D41: =L33 -> 0.98 | E41: =L34 -> 1.5471715 | F41: =(K33-(K32+K34)/2)*12 -> 8.5265128e-14 | G41: =Sp2_C -> 0.56717146 | H41: =IF(ROUND(F41,6)<0,"Case 2",IF(ROUND(F41,6)>G41,"Case 4",IF(ROUND(F41,6)>0,"Case 3","Case 1"))) -> Case 1
A43: E. Mathcad deflections by span (in, + up)
B44: Span | C44: Release (max) | D44: 120 day (max) | E44: Non-comp. DL (min) | F44: Composite DL (min) | G44: Sum = NetCamber | H44: Mathcad NetCamber | I44: CONFIG camber | J44: Check
B45: 1 | C45: =MC1_Drel -> 1.3711622 | D45: =MC1_D120 -> 3.3554493 | E45: =MC1_Dnc -> -2.471606 | F45: =MC1_Dc -> -0.75925047 | G45: =D45+E45+F45 -> 0.12459274 | H45: =MC1_Net -> 0.12459274 | I45: =Sp1_C -> 0.12459274 | J45: =IF(AND(ABS(G45-H45)<0.000000001,ABS(H45-I45)<0.000000001),"PASS","FAIL") -> PASS
B46: 2 | C46: =MC2_Drel -> 1.4647226 | D46: =MC2_D120 -> 3.5081218 | E46: =MC2_Dnc -> -2.2498277 | F46: =MC2_Dc -> -0.69112259 | G46: =D46+E46+F46 -> 0.56717146 | H46: =MC2_Net -> 0.56717146 | I46: =Sp2_C -> 0.56717146 | J46: =IF(AND(ABS(G46-H46)<0.000000001,ABS(H46-I46)<0.000000001),"PASS","FAIL") -> PASS

Sheet Camber & Haunch Method
B1: Camber & Haunch - Method | P1: Figure data
B2: Common support drop D, build-up dimensions and the minimum haunch | P2: Live formulas that draw the charts on this tab. Do not edit; change the notebook CONFIG and rebuild.
B3: =IF(Inputs_Edited=0,"LIVE Charts, tables and the numbers quoted in this text are workbook formulas. Inputs match the notebook build (model "&Build_Model&", built "&Build_Time&").",Inputs_Edited&" INPUT(S) EDITED SINCE THE NOTEBOOK BUILD The charts and tables follow the edited inputs, which no longer match the geometry notebook (QC "&QC_Overall&"). Change the notebook CONFIG and rebuild.") -> LIVE Charts, tables and the numbers quoted in this text are workbook formulas. Inputs match the notebook build (model e9b41b8eaf, built 2026-10-19 12:13).
P4: Span 2: camber and haunch over CL beam 1
B5: 1. Beam soffit with camber | P5: Series / label text | Q5: x | R5: y | S5: error +
B6: Within a span, t runs from 0 at bearing A to 1 at bearing B. The soffit follows the PGL chord between bearings, dropped by one common distance D for every support, plus the Mathcad camber as an upward parabola and any entered beam raise r: | P6: Vertical exaggeration | Q6: =40 -> 40
P7: Deck soffit over CL beam 1 | Q7: =Sp2_Bm0+0/40*(Sp2_Bm1-Sp2_Bm0) -> 1700.695 | R7: =((IF(Prof_Mode="parabolic",Prof_Z0+Prof_G1*(($Q$7)-Prof_Sta0)+Prof_Kq*(($Q$7)-Prof_Sta0)^2,IF(($Q$7)<=Prof_PISta,Prof_Z0+Prof_G1*(($Q$7)-Prof_Sta0),Prof_PIZ+Prof_G2*(($Q$7)-Prof_PISta)))+Bm1_dCL-Deck_T)-((Sp2_ZA+(Sp2_ZB-Sp2_ZA)*(($Q$7)-Sp2_BrgA)/Sp2_Lb)-Sup_Drop+Bm_D+Bm1_Raise/12))*$Q$6 -> 5.1572382
Q8: =Sp2_Bm0+1/40*(Sp2_Bm1-Sp2_Bm0) -> 1703.3081 | R8: =((IF(Prof_Mode="parabolic",Prof_Z0+Prof_G1*(($Q$8)-Prof_Sta0)+Prof_Kq*(($Q$8)-Prof_Sta0)^2,IF(($Q$8)<=Prof_PISta,Prof_Z0+Prof_G1*(($Q$8)-Prof_Sta0),Prof_PIZ+Prof_G2*(($Q$8)-Prof_PISta)))+Bm1_dCL-Deck_T)-((Sp2_ZA+(Sp2_ZB-Sp2_ZA)*(($Q$8)-Sp2_BrgA)/Sp2_Lb)-Sup_Drop+Bm_D+Bm1_Raise/12))*$Q$6 -> 5.1572382
Q9: =Sp2_Bm0+2/40*(Sp2_Bm1-Sp2_Bm0) -> 1705.9212 | R9: =((IF(Prof_Mode="parabolic",Prof_Z0+Prof_G1*(($Q$9)-Prof_Sta0)+Prof_Kq*(($Q$9)-Prof_Sta0)^2,IF(($Q$9)<=Prof_PISta,Prof_Z0+Prof_G1*(($Q$9)-Prof_Sta0),Prof_PIZ+Prof_G2*(($Q$9)-Prof_PISta)))+Bm1_dCL-Deck_T)-((Sp2_ZA+(Sp2_ZB-Sp2_ZA)*(($Q$9)-Sp2_BrgA)/Sp2_Lb)-Sup_Drop+Bm_D+Bm1_Raise/12))*$Q$6 -> 5.1572382
Q10: =Sp2_Bm0+3/40*(Sp2_Bm1-Sp2_Bm0) -> 1708.5344 | R10: =((IF(Prof_Mode="parabolic",Prof_Z0+Prof_G1*(($Q$10)-Prof_Sta0)+Prof_Kq*(($Q$10)-Prof_Sta0)^2,IF(($Q$10)<=Prof_PISta,Prof_Z0+Prof_G1*(($Q$10)-Prof_Sta0),Prof_PIZ+Prof_G2*(($Q$10)-Prof_PISta)))+Bm1_dCL-Deck_T)-((Sp2_ZA+(Sp2_ZB-Sp2_ZA)*(($Q$10)-Sp2_BrgA)/Sp2_Lb)-Sup_Drop+Bm_D+Bm1_Raise/12))*$Q$6 -> 5.1572382
Q11: =Sp2_Bm0+4/40*(Sp2_Bm1-Sp2_Bm0) -> 1711.1475 | R11: =((IF(Prof_Mode="parabolic",Prof_Z0+Prof_G1*(($Q$11)-Prof_Sta0)+Prof_Kq*(($Q$11)-Prof_Sta0)^2,IF(($Q$11)<=Prof_PISta,Prof_Z0+Prof_G1*(($Q$11)-Prof_Sta0),Prof_PIZ+Prof_G2*(($Q$11)-Prof_PISta)))+Bm1_dCL-Deck_T)-((Sp2_ZA+(Sp2_ZB-Sp2_ZA)*(($Q$11)-Sp2_BrgA)/Sp2_Lb)-Sup_Drop+Bm_D+Bm1_Raise/12))*$Q$6 -> 5.1572382
Q12: =Sp2_Bm0+5/40*(Sp2_Bm1-Sp2_Bm0) -> 1713.7606 | R12: =((IF(Prof_Mode="parabolic",Prof_Z0+Prof_G1*(($Q$12)-Prof_Sta0)+Prof_Kq*(($Q$12)-Prof_Sta0)^2,IF(($Q$12)<=Prof_PISta,Prof_Z0+Prof_G1*(($Q$12)-Prof_Sta0),Prof_PIZ+Prof_G2*(($Q$12)-Prof_PISta)))+Bm1_dCL-Deck_T)-((Sp2_ZA+(Sp2_ZB-Sp2_ZA)*(($Q$12)-Sp2_BrgA)/Sp2_Lb)-Sup_Drop+Bm_D+Bm1_Raise/12))*$Q$6 -> 5.1572382
Q13: =Sp2_Bm0+6/40*(Sp2_Bm1-Sp2_Bm0) -> 1716.3737 | R13: =((IF(Prof_Mode="parabolic",Prof_Z0+Prof_G1*(($Q$13)-Prof_Sta0)+Prof_Kq*(($Q$13)-Prof_Sta0)^2,IF(($Q$13)<=Prof_PISta,Prof_Z0+Prof_G1*(($Q$13)-Prof_Sta0),Prof_PIZ+Prof_G2*(($Q$13)-Prof_PISta)))+Bm1_dCL-Deck_T)-((Sp2_ZA+(Sp2_ZB-Sp2_ZA)*(($Q$13)-Sp2_BrgA)/Sp2_Lb)-Sup_Drop+Bm_D+Bm1_Raise/12))*$Q$6 -> 5.1572382
B14: 2. Haunch and the exact minimum | Q14: =Sp2_Bm0+7/40*(Sp2_Bm1-Sp2_Bm0) -> 1718.9869 | R14: =((IF(Prof_Mode="parabolic",Prof_Z0+Prof_G1*(($Q$14)-Prof_Sta0)+Prof_Kq*(($Q$14)-Prof_Sta0)^2,IF(($Q$14)<=Prof_PISta,Prof_Z0+Prof_G1*(($Q$14)-Prof_Sta0),Prof_PIZ+Prof_G2*(($Q$14)-Prof_PISta)))+Bm1_dCL-Deck_T)-((Sp2_ZA+(Sp2_ZB-Sp2_ZA)*(($Q$14)-Sp2_BrgA)/Sp2_Lb)-Sup_Drop+Bm_D+Bm1_Raise/12))*$Q$6 -> 5.1572382
Q15: =Sp2_Bm0+8/40*(Sp2_Bm1-Sp2_Bm0) -> 1721.6 | R15: =((IF(Prof_Mode="parabolic",Prof_Z0+Prof_G1*(($Q$15)-Prof_Sta0)+Prof_Kq*(($Q$15)-Prof_Sta0)^2,IF(($Q$15)<=Prof_PISta,Prof_Z0+Prof_G1*(($Q$15)-Prof_Sta0),Prof_PIZ+Prof_G2*(($Q$15)-Prof_PISta)))+Bm1_dCL-Deck_T)-((Sp2_ZA+(Sp2_ZB-Sp2_ZA)*(($Q$15)-Sp2_BrgA)/Sp2_Lb)-Sup_Drop+Bm_D+Bm1_Raise/12))*$Q$6 -> 5.1572382
Q16: =Sp2_Bm0+9/40*(Sp2_Bm1-Sp2_Bm0) -> 1724.2131 | R16: =((IF(Prof_Mode="parabolic",Prof_Z0+Prof_G1*(($Q$16)-Prof_Sta0)+Prof_Kq*(($Q$16)-Prof_Sta0)^2,IF(($Q$16)<=Prof_PISta,Prof_Z0+Prof_G1*(($Q$16)-Prof_Sta0),Prof_PIZ+Prof_G2*(($Q$16)-Prof_PISta)))+Bm1_dCL-Deck_T)-((Sp2_ZA+(Sp2_ZB-Sp2_ZA)*(($Q$16)-Sp2_BrgA)/Sp2_Lb)-Sup_Drop+Bm_D+Bm1_Raise/12))*$Q$6 -> 5.1572382
Q17: =Sp2_Bm0+10/40*(Sp2_Bm1-Sp2_Bm0) -> 1726.8263 | R17: =((IF(Prof_Mode="parabolic",Prof_Z0+Prof_G1*(($Q$17)-Prof_Sta0)+Prof_Kq*(($Q$17)-Prof_Sta0)^2,IF(($Q$17)<=Prof_PISta,Prof_Z0+Prof_G1*(($Q$17)-Prof_Sta0),Prof_PIZ+Prof_G2*(($Q$17)-Prof_PISta)))+Bm1_dCL-Deck_T)-((Sp2_ZA+(Sp2_ZB-Sp2_ZA)*(($Q$17)-Sp2_BrgA)/Sp2_Lb)-Sup_Drop+Bm_D+Bm1_Raise/12))*$Q$6 -> 5.1572382
B18: Because the PGL is straight (brokeback) or a single parabola over each beam, z_PGL - q is itself -k_q L_b^2 t(1-t). The haunch over a beam is therefore an exact quadratic in t, and its minimum on the beam (t from t_lo to t_hi) has a closed form: | Q18: =Sp2_Bm0+11/40*(Sp2_Bm1-Sp2_Bm0) -> 1729.4394 | R18: =((IF(Prof_Mode="parabolic",Prof_Z0+Prof_G1*(($Q$18)-Prof_Sta0)+Prof_Kq*(($Q$18)-Prof_Sta0)^2,IF(($Q$18)<=Prof_PISta,Prof_Z0+Prof_G1*(($Q$18)-Prof_Sta0),Prof_PIZ+Prof_G2*(($Q$18)-Prof_PISta)))+Bm1_dCL-Deck_T)-((Sp2_ZA+(Sp2_ZB-Sp2_ZA)*(($Q$18)-Sp2_BrgA)/Sp2_Lb)-Sup_Drop+Bm_D+Bm1_Raise/12))*$Q$6 -> 5.1572382
Q19: =Sp2_Bm0+12/40*(Sp2_Bm1-Sp2_Bm0) -> 1732.0525 | R19: =((IF(Prof_Mode="parabolic",Prof_Z0+Prof_G1*(($Q$19)-Prof_Sta0)+Prof_Kq*(($Q$19)-Prof_Sta0)^2,IF(($Q$19)<=Prof_PISta,Prof_Z0+Prof_G1*(($Q$19)-Prof_Sta0),Prof_PIZ+Prof_G2*(($Q$19)-Prof_PISta)))+Bm1_dCL-Deck_T)-((Sp2_ZA+(Sp2_ZB-Sp2_ZA)*(($Q$19)-Sp2_BrgA)/Sp2_Lb)-Sup_Drop+Bm_D+Bm1_Raise/12))*$Q$6 -> 5.1572382
Q20: =Sp2_Bm0+13/40*(Sp2_Bm1-Sp2_Bm0) -> 1734.6656 | R20: =((IF(Prof_Mode="parabolic",Prof_Z0+Prof_G1*(($Q$20)-Prof_Sta0)+Prof_Kq*(($Q$20)-Prof_Sta0)^2,IF(($Q$20)<=Prof_PISta,Prof_Z0+Prof_G1*(($Q$20)-Prof_Sta0),Prof_PIZ+Prof_G2*(($Q$20)-Prof_PISta)))+Bm1_dCL-Deck_T)-((Sp2_ZA+(Sp2_ZB-Sp2_ZA)*(($Q$20)-Sp2_BrgA)/Sp2_Lb)-Sup_Drop+Bm_D+Bm1_Raise/12))*$Q$6 -> 5.1572382
Q21: =Sp2_Bm0+14/40*(Sp2_Bm1-Sp2_Bm0) -> 1737.2787 | R21: =((IF(Prof_Mode="parabolic",Prof_Z0+Prof_G1*(($Q$21)-Prof_Sta0)+Prof_Kq*(($Q$21)-Prof_Sta0)^2,IF(($Q$21)<=Prof_PISta,Prof_Z0+Prof_G1*(($Q$21)-Prof_Sta0),Prof_PIZ+Prof_G2*(($Q$21)-Prof_PISta)))+Bm1_dCL-Deck_T)-((Sp2_ZA+(Sp2_ZB-Sp2_ZA)*(($Q$21)-Sp2_BrgA)/Sp2_Lb)-Sup_Drop+Bm_D+Bm1_Raise/12))*$Q$6 -> 5.1572382
Q22: =Sp2_Bm0+15/40*(Sp2_Bm1-Sp2_Bm0) -> 1739.8919 | R22: =((IF(Prof_Mode="parabolic",Prof_Z0+Prof_G1*(($Q$22)-Prof_Sta0)+Prof_Kq*(($Q$22)-Prof_Sta0)^2,IF(($Q$22)<=Prof_PISta,Prof_Z0+Prof_G1*(($Q$22)-Prof_Sta0),Prof_PIZ+Prof_G2*(($Q$22)-Prof_PISta)))+Bm1_dCL-Deck_T)-((Sp2_ZA+(Sp2_ZB-Sp2_ZA)*(($Q$22)-Sp2_BrgA)/Sp2_Lb)-Sup_Drop+Bm_D+Bm1_Raise/12))*$Q$6 -> 5.1572382
Q23: =Sp2_Bm0+16/40*(Sp2_Bm1-Sp2_Bm0) -> 1742.505 | R23: =((IF(Prof_Mode="parabolic",Prof_Z0+Prof_G1*(($Q$23)-Prof_Sta0)+Prof_Kq*(($Q$23)-Prof_Sta0)^2,IF(($Q$23)<=Prof_PISta,Prof_Z0+Prof_G1*(($Q$23)-Prof_Sta0),Prof_PIZ+Prof_G2*(($Q$23)-Prof_PISta)))+Bm1_dCL-Deck_T)-((Sp2_ZA+(Sp2_ZB-Sp2_ZA)*(($Q$23)-Sp2_BrgA)/Sp2_Lb)-Sup_Drop+Bm_D+Bm1_Raise/12))*$Q$6 -> 5.1572382
Q24: =Sp2_Bm0+17/40*(Sp2_Bm1-Sp2_Bm0) -> 1745.1181 | R24: =((IF(Prof_Mode="parabolic",Prof_Z0+Prof_G1*(($Q$24)-Prof_Sta0)+Prof_Kq*(($Q$24)-Prof_Sta0)^2,IF(($Q$24)<=Prof_PISta,Prof_Z0+Prof_G1*(($Q$24)-Prof_Sta0),Prof_PIZ+Prof_G2*(($Q$24)-Prof_PISta)))+Bm1_dCL-Deck_T)-((Sp2_ZA+(Sp2_ZB-Sp2_ZA)*(($Q$24)-Sp2_BrgA)/Sp2_Lb)-Sup_Drop+Bm_D+Bm1_Raise/12))*$Q$6 -> 5.1572382
B25: t = 1/2 always lies on the beam, so m/4 covers upward camber; the end terms cover a net sag. The notebook finds the same minimum by locating every quadratic extremum between breakpoints. One common drop then enforces the required minimum haunch everywhere: | Q25: =Sp2_Bm0+18/40*(Sp2_Bm1-Sp2_Bm0) -> 1747.7313 | R25: =((IF(Prof_Mode="parabolic",Prof_Z0+Prof_G1*(($Q$25)-Prof_Sta0)+Prof_Kq*(($Q$25)-Prof_Sta0)^2,IF(($Q$25)<=Prof_PISta,Prof_Z0+Prof_G1*(($Q$25)-Prof_Sta0),Prof_PIZ+Prof_G2*(($Q$25)-Prof_PISta)))+Bm1_dCL-Deck_T)-((Sp2_ZA+(Sp2_ZB-Sp2_ZA)*(($Q$25)-Sp2_BrgA)/Sp2_Lb)-Sup_Drop+Bm_D+Bm1_Raise/12))*$Q$6 -> 5.1572382
