Workbook
Name Bar_C: Inputs!$D$210
Name Bar_D3s: Inputs!$D$214
Name Bar_DA: Inputs!$D$211
Name Bar_DB: Inputs!$D$212
Name Bar_MD: Inputs!$D$213
Name Bar_Mk: Inputs!$D$215
Name Bm_Area: Inputs!$D$208
Name Bm_Bf: Inputs!$D$41
Name Bm_D: Inputs!$D$40
Name Bm_First: Inputs!$D$39
Name Bm_Gap1: Inputs!$D$45
Name Bm_Hmin: Inputs!$D$42
Name Bm_N: Inputs!$D$37
Name Bm_S: Inputs!$D$38
Name Bm_Type: Inputs!$D$36
Name Bm1_dCL: 'Profile & Deck'!$I$29
Name Bm1_dMin: 'Profile & Deck'!$L$29
Name Bm1_FL: 'Profile & Deck'!$D$29
Name Bm1_FR: 'Profile & Deck'!$F$29
Name Bm1_Off: 'Profile & Deck'!$C$29
Name Bm1_Raise: Inputs!$D$43
Name Bm2_dCL: 'Profile & Deck'!$I$30
Name Bm2_dMin: 'Profile & Deck'!$L$30
Name Bm2_FL: 'Profile & Deck'!$D$30
Name Bm2_FR: 'Profile & Deck'!$F$30
Name Bm2_Off: 'Profile & Deck'!$C$30
Name Bm2_Raise: Inputs!$D$44
Name Build_Fingerprint: Cover!$C$10
Name Clr_Cover: Clearance!$F$11
Name Clr_Margin: Clearance!$F$10
Name Clr_Min: Clearance!$F$7
Name Clr_Sta: Clearance!$F$8
Name Clr_Status: Clearance!$F$12
Name Deck_C: Inputs!$D$29
Name Deck_Crown: Inputs!$D$31
Name Deck_dL: 'Profile & Deck'!$D$24
Name Deck_dR: 'Profile & Deck'!$D$25
Name Deck_Mode: Inputs!$D$27
Name Deck_T: Inputs!$D$30
Name Deck_Uni: Inputs!$D$32
Name Deck_W: Inputs!$D$28
Name Deck_YL: 'Profile & Deck'!$D$22
Name Deck_YR: 'Profile & Deck'!$D$23
Name Des_BevelLimit: Inputs!$D$206
Name Des_ConcClass: Inputs!$D$202
Name Des_DimP: Inputs!$D$207
Name Des_FGEInc: Inputs!$D$209
Name Des_PadType: Inputs!$D$205
Name Des_Pattern: Inputs!$D$203
Name Des_PlanCase: Inputs!$D$204
Name EB1_BmBrg: Inputs!$D$110
Name EB1_BmClr: Inputs!$D$109
Name EB1_BW: Inputs!$D$107
Name EB1_CapSta: Substructure!$D$9
Name EB1_Chamf: Inputs!$D$106
Name EB1_Ctr: Inputs!$D$102
Name EB1_Depth: Inputs!$D$90
Name EB1_Emb: Inputs!$D$96
Name EB1_Inset: Inputs!$D$108
Name EB1_Len: Substructure!$K$9

Sheet Cover
B2: B4 Pedestrian Bridge - Geometry and CAD Tables
B3: =TB_Project&" | "&TB_Structure -> D2 I-95 Pedestrian Bridge | B4 pedestrian bridge - 2 x FIB-36, two simple spans
B5: Geometry authority | C5: Colab geometry notebook Bridge_Geometry_2 Beam_V2.ipynb (CONFIG + BridgeModel). This workbook reproduces its equations in Excel; the CAD model and these CAD tables are built from it, never the reverse.
B6: Beam design data | C6: Saved results of the two registered Mathcad runs (Span 1, Span 2). Mathcad was not recalculated.
B7: Template methods | C7: Where the notebook is silent (Table of Beam Variables bar dimensions, Dim L/R, build-up case, beveled plates) the BCC example workbook's formulas are used and flagged on the Method tabs.
B8: QC status | C8: =QC_Overall&" ("&QC_Counts&")" -> PASS (150 pass / 0 fail / 1 check)
B9: Rebuild | C9: C:\github\D2MPDB\.venv\Scripts\python.exe scripts\build_geometry_cad_tables.py (rebuilds, recalculates in Excel, verifies)
B10: Build fingerprint | C10: 7c2bc2fb909d765c0208
B11: Generator version | C11: 1.0.0
B12: Built | C12: 2026-10-16 09:32
B13: Notebook model ID | C13: 4d5b58a9ac
B15: Sources
B16: Geometry notebook | C16: Bridge_Geometry_2 Beam_V2.ipynb (lf_text) SHA-256 f222fe4cd0d695786101295736928be11f07b0b70eba55493a30cfaea4644400
B17: Roadway XML | C17: Geometry Report.xml SHA-256 9880ef7adeeac4228666146f5d5bb4dd17ef93f66ffeaf465a2c813eb69489e4
B18: Mathcad Span 1 | C18: project_current/mathcad/PrestressedBeamV6.2_Pedestrian_2Beam_Span1.xmcd SHA-256 a6b0f967d271c193591d477e219ac66f98b72309d19958a04c6cd08e575a8dcd
B19: Mathcad Span 2 | C19: project_current/mathcad/PrestressedBeamV6.2_Pedestrian_2Beam_Span2.xmcd SHA-256 182e3471f169d3a379c437ad12f359d567813bd4631bcc0b82e78ad860fa91b8
B21: Tabs
B22: Inputs | C22: All inputs with provenance (notebook CONFIG, Mathcad saved results, designer/template constants).
B23: Inputs Method | C23: Method for Inputs: equations, explanation and schematics.
B24: Profile & Deck | C24: PGL grades, deck edges, beam offsets and haunch check points.
B25: Profile & Deck Method | C25: Method for Profile & Deck: equations, explanation and schematics.
B26: Beam Geometry | C26: Physical beam ends, bearings, chords; Dims J, K, P, L and shortening R.
B27: Beam Geometry Method | C27: Method for Beam Geometry: equations, explanation and schematics.
B28: Camber & Haunch | C28: Common support drop D, build-up Dims B/C/D, minimum haunch, Mathcad deflections.
B29: Camber & Haunch Method | C29: Method for Camber & Haunch: equations, explanation and schematics.
B30: FGE | C30: Finished grade elevations at every line and station.
B31: FGE Method | C31: Method for FGE: equations, explanation and schematics.
B32: Bearing Seats | C32: Seat planes, slopes, pedestal tops and corners, bearing plate data.
B33: Bearing Seats Method | C33: Method for Bearing Seats: equations, explanation and schematics.
... B51: QC Method | C51: Method for QC: equations, explanation and schematics.
B53: Cell legend
B54: Input (generated from notebook / Mathcad)
B55: Calculated in this tab
B56: Linked from another tab
B57: PASS
B58: FAIL
B59: CHECK / review
B61: Open items
C62: - End-bent caps and cheek walls (D-026/D-027/D-033) are being added to the notebook in a separate task; rebuild this workbook afterwards.
C63: - Deck barrier (D-031, 12 ft clear) is not in the notebook, so no barrier-face FGE line is tabulated.
...

Sheet Inputs
A1: Inputs
A2: Blue values on yellow are inputs. Every geometry input is generated from the Colab geometry notebook CONFIG (the geometry authority); beam-design inputs come from the saved Mathcad runs. Edit the notebook and rebuild rather than editing these cells; QC flags any drift.
A4: Title block (fill in)
B5: Parameter | C5: Symbol | D5: Value | E5: Unit | F5: Workbook name | G5: Source / note
B6: Project | D6: D2 I-95 Pedestrian Bridge | F6: TB_Project | G6: Project journal name; edit as needed
B7: Structure | D7: B4 pedestrian bridge - 2 x FIB-36, two simple spans | F7: TB_Structure | G7: FreeCAD model / Mathcad beam type; edit as needed
B8: Job No. | F8: TB_JobNo | G8: Not in project sources - enter
B9: Calculated by | F9: TB_CalcBy | G9: Enter
B10: Date (calculated) | F10: TB_CalcDate | G10: Enter
B11: Checked by | F11: TB_CheckBy | G11: Enter
B12: Date (checked) | F12: TB_CheckDate | G12: Enter
A14: Profile - CONFIG['profile']
B15: Parameter | C15: Symbol | D15: Value | E15: Unit | F15: Workbook name | G15: Source / note
B16: Profile mode (brokeback or parabolic) | C16: mode | D16: brokeback | F16: Prof_Mode | G16: Notebook CONFIG profile.mode
B17: Profile start station (FFBW End Bent 1) | C17: s0 | D17: 1593.22 | E17: ft | F17: Prof_Sta0 | G17: Notebook CONFIG profile.start_sta_ft
B18: Profile end station (FFBW End Bent 2) | C18: s1 | D18: 1805.47 | E18: ft | F18: Prof_Sta1 | G18: Notebook CONFIG profile.end_sta_ft
B19: Start elevation | C19: z0 | D19: 47.661 | E19: ft | F19: Prof_Z0 | G19: Notebook CONFIG profile.start_elev_ft
B20: End elevation | C20: z1 | D20: 47.673 | E20: ft | F20: Prof_Z1 | G20: Notebook CONFIG profile.end_elev_ft
B21: Tangent intersection station (PI) | C21: sPI | D21: 1700.57 | E21: ft | F21: Prof_PISta | G21: Notebook CONFIG profile.intersection_sta_ft
B22: Nominal tangent grade (brokeback) | C22: g | D22: 0.005 | E22: ft/ft | F22: Prof_Gnom | G22: Notebook CONFIG profile.nominal_grade
B23: Grade change (parabolic mode only) | C23: dg | D23: -0.01 | E23: ft/ft | F23: Prof_dG | G23: Notebook CONFIG profile.parabolic_grade_change
A25: Deck - CONFIG['deck']
B26: Parameter | C26: Symbol | D26: Value | E26: Unit | F26: Workbook name | G26: Source / note
B27: Deck mode (crowned or uniform) | C27: mode | D27: crowned | F27: Deck_Mode | G27: Notebook CONFIG deck.mode. Transition mode is not implemented in this workbook (QC fails).
B28: Deck width | C28: W | D28: 13.583333 | E28: ft | F28: Deck_W | G28: Notebook CONFIG deck.width_ft (13 ft 7 in from DXF *D5380)
B29: Deck center offset from PGL | C29: yc | D29: 0 | E29: ft | F29: Deck_C | G29: Notebook CONFIG deck.center_offset_ft
B30: Deck thickness | C30: td | D30: 0.5 | E30: ft | F30: Deck_T | G30: Notebook CONFIG deck.thickness_ft
B31: Crown slope (each side, away from PGL) | C31: sc | D31: -0.02 | E31: ft/ft | F31: Deck_Crown | G31: Notebook CONFIG deck.crown_slope
B32: Uniform cross slope (uniform mode only) | C32: su | D32: -0.02 | E32: ft/ft | F32: Deck_Uni | G32: Notebook CONFIG deck.uniform_slope
A34: Beams - CONFIG['beams']
B35: Parameter | C35: Symbol | D35: Value | E35: Unit | F35: Workbook name | G35: Source / note
B36: Beam type | D36: FIB-36 | F36: Bm_Type | G36: Mathcad BeamType (notebook models the FIB-36 outline)
B37: Number of beams | C37: N | D37: 2 | F37: Bm_N | G37: Notebook CONFIG beams.count (table layout is generated for this count)
B38: Beam spacing | C38: S | D38: 8.5833333 | E38: ft | F38: Bm_S | G38: Notebook CONFIG beams.spacing_ft
B39: First beam offset (blank = centered on PGL) | C39: y1 | E39: ft | F39: Bm_First | G39: Notebook CONFIG beams.first_offset_ft
B40: Beam depth | C40: db | D40: 3 | E40: ft | F40: Bm_D | G40: Notebook CONFIG beams.depth_ft
B41: Top flange width | C41: bf | D41: 48 | E41: in | F41: Bm_Bf | G41: Notebook CONFIG beams.top_flange_width_in
B42: Minimum haunch (at any flange point) | C42: hmin | D42: 0.5 | E42: in | F42: Bm_Hmin | G42: Notebook CONFIG beams.minimum_haunch_in
B43: Beam 1 vertical raise | C43: r1 | D43: 0 | E43: in | F43: Bm1_Raise | G43: Notebook CONFIG beams.raise_in
B44: Beam 2 vertical raise | C44: r2 | D44: 0 | E44: in | F44: Bm2_Raise | G44: Notebook CONFIG beams.raise_in
...

Sheet Inputs Method
B1: Inputs - Method
B2: Where every input comes from and how the workbook is kept consistent with the notebook
B5: 1. Authority and data flow
B6: The Colab geometry notebook (Bridge_Geometry_2 Beam_V2.ipynb) is the source of truth for all bridge geometry. Its CONFIG dictionary and BridgeModel equations define the profile, deck, beam layout, bearings, caps, pedestals and piles. The FreeCAD model and these CAD tables are built from the notebook, never the reverse. The generator executes the notebook cells, writes CONFIG into this tab, and writes every calculation as an Excel formula.
B20: Figure 1. Source-to-table flow. Each arrow is a formula chain you can trace with Excel "Trace Precedents".
B22: 2. Sign conventions and units
B23: • Stations s increase from End Bent 1 to End Bent 2 (ft). Offsets y are measured from the PGL, positive to the right looking up-station (ft).
B24: • Elevations z are in feet on the project datum. Inputs ending in "in" are inches; slopes and grades are ft/ft.
B25: • Deflections and camber are in inches, positive upward (Mathcad convention). The camber C is the peak upward value at midspan.
B26: • Workbook names (Formulas > Name Manager) mirror the notebook keys, for example Prof_Sta0 = CONFIG["profile"]["start_sta_ft"].
B28: 3. Mathcad beam-design values
B29: Beam-design inputs are the saved results stored in the two registered Mathcad runs. The generator parses the worksheet XML and reads each result by variable name; Mathcad is not recalculated. The notebook camber input equals the Mathcad NetCamber:
B33: Span 1: C = 0.124593 in; Span 2: C = 0.567171 in. QC confirms the deflection sum, the Mathcad NetCamber and the notebook CONFIG camber agree.
B34: Symbol | C34: Meaning | H34: Workbook name / location | K34: Units / value
B35: C | C35: Net camber at 120 days after all dead load | H35: Sp1_C, Sp2_C (Inputs) | K35: in
B36: Δ120 | C36: 120-day prestress + beam weight deflection (max) | H36: MC1_D120, MC2_D120 | K36: in
B37: ΔDL,nc | C37: Non-composite dead load (deck pour) deflection (min) | H37: MC1_Dnc, MC2_Dnc | K37: in
B38: ΔDL,c | C38: Composite dead load (barrier) deflection (min) | H38: MC1_Dc, MC2_Dc | K38: in
B39: ψ, εsh | C39: Creep coefficient and shrinkage strain at 120 days | H39: MC1_Psi, MC1_Esh ... | K39: -
B42: 4. Designer assignments and template constants
B43: A few table entries are not geometry and are not in Mathcad: concrete class, strand pattern number, plan view case and pad type. They are explicit inputs at the bottom of the Inputs tab. Standard bar-bending constants for the Table of Beam Variables are taken from the BCC example workbook formulas so the tables are produced the same way as before.
B45: 5. Keeping it current
B46: • Change geometry in the notebook CONFIG, then run: .venv\Scripts\python.exe scripts\build_geometry_cad_tables.py
B47: • The script rebuilds every tab, has Excel recalculate, and verifies the results against the notebook before saving.
B48: • Editing a blue input here recalculates the workbook, but the QC tab will then flag the difference from the notebook.
B49: • Build fingerprint 7c2bc2fb909d765c0208; notebook model ID 4d5b58a9ac. The regression test fails if any source or the generator changes without a rebuild.

Sheet Profile & Deck
A1: Profile & Deck | K1: Project | L1: =""&TB_Project -> D2 I-95 Pedestrian Bridge
A2: PGL profile, deck cross slope, beam offsets and haunch check points | K2: Job No. | L2: =""&TB_JobNo
K3: Calc. by / date | L3: =TB_CalcBy&" "&TB_CalcDate
K4: Check. by / date | L4: =TB_CheckBy&" "&TB_CheckDate
A6: Profile constants
B7: Parameter | C7: Symbol | D7: Value | E7: Unit | F7: Workbook name | G7: Source / note
B8: Profile length | C8: L | D8: =Prof_Sta1-Prof_Sta0 -> 212.25 | E8: ft | F8: Prof_L | G8: s1 - s0
B9: PI elevation (brokeback) | C9: zPI | D9: =(Prof_Z0+Prof_Gnom*(Prof_PISta-Prof_Sta0)+Prof_Z1+Prof_Gnom*(Prof_Sta1-Prof_PISta))/2 -> 48.197625 | E9: ft | F9: Prof_PIZ | G9: Average of the two tangents projected to the PI
B10: Grade 1 (entering) | C10: g1 | D10: =IF(Prof_Mode="parabolic",(Prof_Z1-Prof_Z0)/Prof_L-Prof_dG/2,(Prof_PIZ-Prof_Z0)/(Prof_PISta-Prof_Sta0)) -> 0.0049988356 | E10: ft/ft | F10: Prof_G1 | G10: Notebook BridgeModel.__init__
B11: Grade 2 (leaving) | C11: g2 | D11: =IF(Prof_Mode="parabolic",Prof_G1+Prof_dG,(Prof_Z1-Prof_PIZ)/(Prof_Sta1-Prof_PISta)) -> -0.0050011916 | E11: ft/ft | F11: Prof_G2 | G11: Notebook BridgeModel.__init__
B12: Parabolic coefficient (0 for brokeback) | C12: kq | D12: =IF(Prof_Mode="parabolic",0.5*(Prof_G2-Prof_G1)/Prof_L,0) -> 0 | E12: 1/ft | F12: Prof_Kq | G12: z = z0 + g1 x + kq x^2
A14: PGL at control stations
B15: Control point | C15: Station (ft) | D15: PGL (ft) | E15: Station label
B16: FFBW End Bent 1 (profile start) | C16: =Prof_Sta0 -> 1593.22 | D16: =IF(Prof_Mode="parabolic",Prof_Z0+Prof_G1*((C16)-Prof_Sta0)+Prof_Kq*((C16)-Prof_Sta0)^2,IF((C16)<=Prof_PISta,Prof_Z0+Prof_G1*((C16)-Prof_Sta0),Prof_PIZ+Prof_G2*((C16)-Prof_PISta))) -> 47.661 | E16: =TEXT(INT(ROUND(C16*100,0)/10000),"0")&"+"&TEXT(MOD(ROUND(C16*100,0),10000)/100,"00.00") -> 15+93.22
B17: Tangent intersection (PI) | C17: =Prof_PISta -> 1700.57 | D17: =IF(Prof_Mode="parabolic",Prof_Z0+Prof_G1*((C17)-Prof_Sta0)+Prof_Kq*((C17)-Prof_Sta0)^2,IF((C17)<=Prof_PISta,Prof_Z0+Prof_G1*((C17)-Prof_Sta0),Prof_PIZ+Prof_G2*((C17)-Prof_PISta))) -> 48.197625 | E17: =TEXT(INT(ROUND(C17*100,0)/10000),"0")&"+"&TEXT(MOD(ROUND(C17*100,0),10000)/100,"00.00") -> 17+00.57
B18: FFBW End Bent 2 (profile end) | C18: =Prof_Sta1 -> 1805.47 | D18: =IF(Prof_Mode="parabolic",Prof_Z0+Prof_G1*((C18)-Prof_Sta0)+Prof_Kq*((C18)-Prof_Sta0)^2,IF((C18)<=Prof_PISta,Prof_Z0+Prof_G1*((C18)-Prof_Sta0),Prof_PIZ+Prof_G2*((C18)-Prof_PISta))) -> 47.673 | E18: =TEXT(INT(ROUND(C18*100,0)/10000),"0")&"+"&TEXT(MOD(ROUND(C18*100,0),10000)/100,"00.00") -> 18+05.47
A20: Deck edges
B21: Parameter | C21: Symbol | D21: Value | E21: Unit | F21: Workbook name | G21: Source / note
B22: Left deck edge (coping) offset | D22: =Deck_C-Deck_W/2 -> -6.7916667 | E22: ft | F22: Deck_YL | G22: Offsets measured from the PGL, + to the right looking up-station
B23: Right deck edge (coping) offset | D23: =Deck_C+Deck_W/2 -> 6.7916667 | E23: ft | F23: Deck_YR
B24: Deck cross-slope drop at left edge | D24: =IF(Deck_Mode="uniform",Deck_Uni*(Deck_YL),Deck_Crown*ABS(Deck_YL)) -> -0.13583333 | E24: ft | F24: Deck_dL | G24: delta(y)
B25: Deck cross-slope drop at right edge | D25: =IF(Deck_Mode="uniform",Deck_Uni*(Deck_YR),Deck_Crown*ABS(Deck_YR)) -> -0.13583333 | E25: ft | F25: Deck_dR | G25: delta(y)
A27: Beam lines and haunch check points (flange edges, CL and any crown point on the flange)
B28: Beam | C28: Offset y (ft) | D28: Left flange edge | E28: CL | F28: Right flange edge | G28: Crown point on flange | H28: delta left (ft) | I28: delta CL (ft) | J28: delta right (ft) | K28: delta crown pt (ft) | L28: delta min (ft)
B29: Beam 1 | C29: =IF(ISNUMBER(Bm_First),Bm_First,-(Bm_Gap1)/2) -> -4.2916667 | D29: =C29-Bm_Bf/24 -> -6.2916667 | E29: =C29 -> -4.2916667 | F29: =C29+Bm_Bf/24 -> -2.2916667 | G29: =MAX(D29,MIN(0,F29)) -> -2.2916667 | H29: =IF(Deck_Mode="uniform",Deck_Uni*(D29),Deck_Crown*ABS(D29)) -> -0.12583333 | I29: =IF(Deck_Mode="uniform",Deck_Uni*(E29),Deck_Crown*ABS(E29)) -> -0.085833333 | J29: =IF(Deck_Mode="uniform",Deck_Uni*(F29),Deck_Crown*ABS(F29)) -> -0.045833333 | K29: =IF(Deck_Mode="uniform",Deck_Uni*(G29),Deck_Crown*ABS(G29)) -> -0.045833333 | L29: =MIN(H29:K29) -> -0.12583333
B30: Beam 2 | C30: =Bm1_Off+Bm_Gap1 -> 4.2916667 | D30: =C30-Bm_Bf/24 -> 2.2916667 | E30: =C30 -> 4.2916667 | F30: =C30+Bm_Bf/24 -> 6.2916667 | G30: =MAX(D30,MIN(0,F30)) -> 2.2916667 | H30: =IF(Deck_Mode="uniform",Deck_Uni*(D30),Deck_Crown*ABS(D30)) -> -0.045833333 | I30: =IF(Deck_Mode="uniform",Deck_Uni*(E30),Deck_Crown*ABS(E30)) -> -0.085833333 | J30: =IF(Deck_Mode="uniform",Deck_Uni*(F30),Deck_Crown*ABS(F30)) -> -0.12583333 | K30: =IF(Deck_Mode="uniform",Deck_Uni*(G30),Deck_Crown*ABS(G30)) -> -0.045833333 | L30: =MIN(H30:K30) -> -0.12583333
A32: Layout checks
B33: Beam flanges inside the deck width | C33: =IF(AND(Bm1_FL>=Deck_YL-0.000000001,Bm2_FR<=Deck_YR+0.000000001),"PASS","FAIL") -> PASS
B34: Flanges do not overlap | C34: =IF(MIN(Bm_Gap1)>=Bm_Bf/12-0.000000001,"PASS","FAIL") -> PASS
B35: Deck mode implemented (crowned or uniform) | C35: =IF(OR(Deck_Mode="crowned",Deck_Mode="uniform"),"PASS","FAIL") -> PASS
B36: Profile mode implemented (brokeback or parabolic) | C36: =IF(OR(Prof_Mode="brokeback",Prof_Mode="parabolic"),"PASS","FAIL") -> PASS
B37: PI inside the profile | C37: =IF(AND(Prof_PISta>Prof_Sta0,Prof_PISta<Prof_Sta1),"PASS","FAIL") -> PASS

Sheet Profile & Deck Method
B1: Profile & Deck - Method
B2: Profile grade line, deck cross slope, beam offsets and haunch check points
B5: 1. Profile grade line (PGL)
B6: The notebook profile mode is "brokeback". In brokeback mode the PGL is two straight tangents of nominal grade g that meet at the tangent intersection station. The PI elevation averages the two tangents projected to the PI, which preserves both end elevations:
B16: Current values: g1 = +0.499884%, g2 = -0.500119%, z_PI = 48.197625 ft at 17+00.57.
B17: Parabolic mode (also in the notebook) keeps both end elevations and the entered grade change Δg, with x = s - s0 and L = s1 - s0:
B37: Figure 1. Profile along the bridge (vertical scale exaggerated).
B39: 2. Deck surface
B40: The deck top at offset y adds a cross-slope term to the PGL. Crowned mode slopes both sides away from the PGL; uniform mode applies one slope across the deck. (The notebook transition mode is not implemented in this workbook; QC fails if it is selected.)
B60: Figure 2. Typical section and haunch check points.
B62: 3. Beam offsets and haunch check points
B66: The haunch is checked at four transverse points on each top flange: both flange edges, the beam centerline, and the crown point clipped onto the flange (it captures a crown break that falls on the flange). The lowest deck point over the flange governs:
B70: Symbol | C70: Meaning | H70: Workbook name / location | K70: Units / value
B71: s0, s1, sPI | C71: Profile start, end and tangent-intersection stations | H71: Prof_Sta0, Prof_Sta1, Prof_PISta | K71: ft
B72: z0, z1 | C72: Profile end elevations | H72: Prof_Z0, Prof_Z1 | K72: ft
B73: g1, g2 | C73: Tangent grades | H73: Prof_G1, Prof_G2 | K73: ft/ft
B74: kq | C74: Parabolic coefficient (0 in brokeback mode) | H74: Prof_Kq | K74: 1/ft
B75: sc, su | C75: Crown slope, uniform slope | H75: Deck_Crown, Deck_Uni | K75: ft/ft
B76: yk | C76: Beam k centerline offset | H76: Bm1_Off, Bm2_Off | K76: ft
B77: δmin,k | C77: Lowest cross-slope drop over beam k flange | H77: Bm1_dMin, Bm2_dMin | K77: ft

Sheet Beam Geometry
A1: Beam Geometry | O1: Project | P1: =""&TB_Project -> D2 I-95 Pedestrian Bridge
A2: Physical beam ends, bearings, deck limits, bearing chords and Table of Beam Variables dimensions | O2: Job No. | P2: =""&TB_JobNo
O3: Calc. by / date | P3: =TB_CalcBy&" "&TB_CalcDate
O4: Check. by / date | P4: =TB_CheckBy&" "&TB_CheckDate
A6: Span layout (stations in ft)
B7: Span | C7: Datum start | D7: Datum end | E7: Start support | F7: End support | G7: Beam start | H7: Beam end | I7: CL brg A (start) | J7: CL brg B (end) | K7: Deck start | L7: Deck end | M7: Beam length | N7: Brg span Lb | O7: Brg midpoint | P7: PGL at A | Q7: PGL at B | R7: Chord grade | S7: Layout check | T7: Mathcad L.beam | U7: Beam length - Mathcad
B8: 1 | C8: =Sp1_Sta0 -> 1593.22 | D8: =Sp1_Sta1 -> 1700.57 | E8: End Bent 1 | F8: Pier | G8: =C8+Phys_EndClr/12 -> 1593.47 | H8: =D8-Phys_PierGap/24 -> 1700.445 | I8: =G8+Phys_Setback/12 -> 1594.22 | J8: =H8-Phys_Setback/12 -> 1699.695 | K8: =C8+Phys_DeckClr/12 -> 1593.47 | L8: =D8 -> 1700.57 | M8: =H8-G8 -> 106.975 | N8: =J8-I8 -> 105.475 | O8: =(I8+J8)/2 -> 1646.9575 | P8: =IF(Prof_Mode="parabolic",Prof_Z0+Prof_G1*((I8)-Prof_Sta0)+Prof_Kq*((I8)-Prof_Sta0)^2,IF((I8)<=Prof_PISta,Prof_Z0+Prof_G1*((I8)-Prof_Sta0),Prof_PIZ+Prof_G2*((I8)-Prof_PISta))) -> 47.665999 | Q8: =IF(Prof_Mode="parabolic",Prof_Z0+Prof_G1*((J8)-Prof_Sta0)+Prof_Kq*((J8)-Prof_Sta0)^2,IF((J8)<=Prof_PISta,Prof_Z0+Prof_G1*((J8)-Prof_Sta0),Prof_PIZ+Prof_G2*((J8)-Prof_PISta))) -> 48.193251 | R8: =(Q8-P8)/N8 -> 0.0049988356 | S8: =IF(AND(C8<=G8,G8<I8,I8<J8,J8<H8,H8<=D8,K8<L8),"PASS","FAIL") -> PASS | T8: =MC1_Lbeam -> 106.975 | U8: =M8-T8 -> 0
B9: 2 | C9: =Sp2_Sta0 -> 1700.57 | D9: =Sp2_Sta1 -> 1805.47 | E9: Pier | F9: End Bent 2 | G9: =C9+Phys_PierGap/24 -> 1700.695 | H9: =D9-Phys_EndClr/12 -> 1805.22 | I9: =G9+Phys_Setback/12 -> 1701.445 | J9: =H9-Phys_Setback/12 -> 1804.47 | K9: =C9 -> 1700.57 | L9: =D9-Phys_DeckClr/12 -> 1805.22 | M9: =H9-G9 -> 104.525 | N9: =J9-I9 -> 103.025 | O9: =(I9+J9)/2 -> 1752.9575 | P9: =IF(Prof_Mode="parabolic",Prof_Z0+Prof_G1*((I9)-Prof_Sta0)+Prof_Kq*((I9)-Prof_Sta0)^2,IF((I9)<=Prof_PISta,Prof_Z0+Prof_G1*((I9)-Prof_Sta0),Prof_PIZ+Prof_G2*((I9)-Prof_PISta))) -> 48.193249 | Q9: =IF(Prof_Mode="parabolic",Prof_Z0+Prof_G1*((J9)-Prof_Sta0)+Prof_Kq*((J9)-Prof_Sta0)^2,IF((J9)<=Prof_PISta,Prof_Z0+Prof_G1*((J9)-Prof_Sta0),Prof_PIZ+Prof_G2*((J9)-Prof_PISta))) -> 47.678001 | R9: =(Q9-P9)/N9 -> -0.0050011916 | S9: =IF(AND(C9<=G9,G9<I9,I9<J9,J9<H9,H9<=D9,K9<L9),"PASS","FAIL") -> PASS | T9: =MC2_Lbeam -> 104.525 | U9: =M9-T9 -> 0
A11: Beam dimensions for the Table of Beam Variables (template method, notebook geometry)
B12: Beam | C12: Span | D12: Offset (ft) | E12: Raise (in) | F12: Horizontal length (ft) | G12: Sloped length Ls (ft) | H12: Skew (deg) | I12: Angle phi End 1 | J12: Angle phi End 2 | K12: Dim J (in) | L12: Dim K1 (in) | M12: Dim K2 (in) | N12: Dim P (in) | O12: End elev. cond. | P12: Prestress P (kip) | Q12: Creep factor C1 | R12: Shortening R (in) | S12: Dim L incl. R (ft) | T12: Dim L ft | U12: Dim L in
B13: 1-1 | C13: 1 | D13: =Bm1_Off -> -4.2916667 | E13: =Bm1_Raise -> 0 | F13: =Sp1_LBeam -> 106.975 | G13: =F13*SQRT(1+Sp1_Gc^2) -> 106.97634 | H13: =MC1_Skew -> 0 | I13: =90-H13 -> 90 | J13: =90-H13 -> 90 | K13: =Phys_Setback -> 9 | L13: =(Sp1_BrgA-Sp1_Sta0)*12 -> 12 | M13: =(Sp1_Sta1-Sp1_BrgB)*12 -> 10.5 | N13: =IF(ABS(Sp1_Gc*Bm_D*12)<Des_DimP,0,-Sp1_Gc*Bm_D*12) -> 0 | O13: =IF(N13<0,2,IF(N13>0,3,1)) -> 1 | P13: =MC1_NStr*MC1_Pj+MC1_NTop*MC1_PTop -> 1753.7575 | Q13: =1+MC1_Psi -> 1.9583197 | R13: =Q13*P13*G13*12/(MC1_Eci*Bm_Area)+ABS(MC1_Esh)*G13*12 -> 1.5229584 | S13: =G13+R13/12 -> 107.10325 | T13: =ROUNDDOWN(S13,0) -> 107 | U13: =(S13-T13)*12 -> 1.238997
B14: 1-2 | C14: 1 | D14: =Bm2_Off -> 4.2916667 | E14: =Bm2_Raise -> 0 | F14: =Sp1_LBeam -> 106.975 | G14: =F14*SQRT(1+Sp1_Gc^2) -> 106.97634 | H14: =MC1_Skew -> 0 | I14: =90-H14 -> 90 | J14: =90-H14 -> 90 | K14: =Phys_Setback -> 9 | L14: =(Sp1_BrgA-Sp1_Sta0)*12 -> 12 | M14: =(Sp1_Sta1-Sp1_BrgB)*12 -> 10.5 | N14: =IF(ABS(Sp1_Gc*Bm_D*12)<Des_DimP,0,-Sp1_Gc*Bm_D*12) -> 0 | O14: =IF(N14<0,2,IF(N14>0,3,1)) -> 1 | P14: =MC1_NStr*MC1_Pj+MC1_NTop*MC1_PTop -> 1753.7575 | Q14: =1+MC1_Psi -> 1.9583197 | R14: =Q14*P14*G14*12/(MC1_Eci*Bm_Area)+ABS(MC1_Esh)*G14*12 -> 1.5229584 | S14: =G14+R14/12 -> 107.10325 | T14: =ROUNDDOWN(S14,0) -> 107 | U14: =(S14-T14)*12 -> 1.238997
B15: 2-1 | C15: 2 | D15: =Bm1_Off -> -4.2916667 | E15: =Bm1_Raise -> 0 | F15: =Sp2_LBeam -> 104.525 | G15: =F15*SQRT(1+Sp2_Gc^2) -> 104.52631 | H15: =MC2_Skew -> 0 | I15: =90-H15 -> 90 | J15: =90-H15 -> 90 | K15: =Phys_Setback -> 9 | L15: =(Sp2_BrgA-Sp2_Sta0)*12 -> 10.5 | M15: =(Sp2_Sta1-Sp2_BrgB)*12 -> 12 | N15: =IF(ABS(Sp2_Gc*Bm_D*12)<Des_DimP,0,-Sp2_Gc*Bm_D*12) -> 0 | O15: =IF(N15<0,2,IF(N15>0,3,1)) -> 1 | P15: =MC2_NStr*MC2_Pj+MC2_NTop*MC2_PTop -> 1753.7575 | Q15: =1+MC2_Psi -> 1.9583197 | R15: =Q15*P15*G15*12/(MC2_Eci*Bm_Area)+ABS(MC2_Esh)*G15*12 -> 1.4880787 | S15: =G15+R15/12 -> 104.65031 | T15: =ROUNDDOWN(S15,0) -> 104 | U15: =(S15-T15)*12 -> 7.8037649
B16: 2-2 | C16: 2 | D16: =Bm2_Off -> 4.2916667 | E16: =Bm2_Raise -> 0 | F16: =Sp2_LBeam -> 104.525 | G16: =F16*SQRT(1+Sp2_Gc^2) -> 104.52631 | H16: =MC2_Skew -> 0 | I16: =90-H16 -> 90 | J16: =90-H16 -> 90 | K16: =Phys_Setback -> 9 | L16: =(Sp2_BrgA-Sp2_Sta0)*12 -> 10.5 | M16: =(Sp2_Sta1-Sp2_BrgB)*12 -> 12 | N16: =IF(ABS(Sp2_Gc*Bm_D*12)<Des_DimP,0,-Sp2_Gc*Bm_D*12) -> 0 | O16: =IF(N16<0,2,IF(N16>0,3,1)) -> 1 | P16: =MC2_NStr*MC2_Pj+MC2_NTop*MC2_PTop -> 1753.7575 | Q16: =1+MC2_Psi -> 1.9583197 | R16: =Q16*P16*G16*12/(MC2_Eci*Bm_Area)+ABS(MC2_Esh)*G16*12 -> 1.4880787 | S16: =G16+R16/12 -> 104.65031 | T16: =ROUNDDOWN(S16,0) -> 104 | U16: =(S16-T16)*12 -> 7.8037649
B18: Dim L follows the BCC template (sloped beam length + shortening R). Confirm against the current FDOT instructions for the Table of Beam Variables before issue; the sloped length without R is column G.

Sheet Beam Geometry Method
B1: Beam Geometry - Method
B2: Physical beam ends, bearings and the Table of Beam Variables dimensions
B5: 1. Physical beam ends and bearings
B6: Spans run between datums: the front face of backwall (FFBW) at end bents and the pier centerline. Beams stop short of each datum by the beam-end clearance e at an end bent, or by half the pier gap g at the pier. Bearings sit a setback j inside each beam end. The deck stops a clearance cd inside each FFBW and is continuous over the pier:
B10: Current: e = 3 in, g = 3 in, j = 9 in, cd = 3 in. Span 1 bearings 15+94.22 to 16+99.70; Span 2 bearings 17+01.44 to 18+04.47.
B25: Figure 1. Beam-end, bearing and pier-joint dimensions (elevation).
B27: 2. Bearing chord and sloped length
B31: The beam soffit chord between bearings is parallel to the PGL chord (the notebook drops all bearings by the same D; see Camber & Haunch). QC compares the horizontal beam length with the Mathcad L.beam.
B33: 3. Table of Beam Variables dimensions (BCC template method)
B40: Elastic plus time-dependent shortening R uses the template expression with the Mathcad prestress, creep and shrinkage values:
B47: Dim L adds R to the sloped length, exactly as the BCC template did. Confirm against the current FDOT Table of Beam Variables instructions before issue; the sloped length without R is shown in the Ls column.
B61: Figure 2. End-of-beam dimensions used in the Table of Beam Variables.
B62: Symbol | C62: Meaning | H62: Workbook name / location | K62: Units / value
B63: sa, sb | C63: Span datum stations (FFBW or CL pier) | H63: Sp1_Sta0, Sp1_Sta1 ... | K63: ft
B64: sA, sB | C64: Bearing stations | H64: Sp1_BrgA, Sp1_BrgB ... | K64: ft
B65: Lb, gc | C65: Bearing span and chord grade | H65: Sp1_Lb, Sp1_Gc ... | K65: ft, ft/ft
B66: P | C66: Total prestress force at jacking | H66: Beam Geometry col P | K66: kip
B67: Ag, Eci | C67: FIB-36 gross area; release modulus (Mathcad) | H67: Bm_Area, MC1_Eci | K67: in2, ksi

Sheet Camber & Haunch
A1: Camber & Haunch | L1: Project | M1: =""&TB_Project -> D2 I-95 Pedestrian Bridge
A2: Common support drop, build-up (Dims B, C, D) and minimum flange haunch | L2: Job No. | M2: =""&TB_JobNo
L3: Calc. by / date | M3: =TB_CalcBy&" "&TB_CalcDate
L4: Check. by / date | M4: =TB_CheckBy&" "&TB_CheckDate
A6: A. Haunch shape per span: h(t) = K - m t(1-t), with t = (s - brg A)/Lb
B7: Span | C7: Camber C (in) | D7: Lb (ft) | E7: t at beam start | F7: t at beam end | G7: m (ft) | H7: max of m t(1-t) on beam | I7: Mathcad NetCamber (in) | J7: C - Mathcad (in)
B8: 1 | C8: =Sp1_C -> 0.12459274 | D8: =Sp1_Lb -> 105.475 | E8: =(Sp1_Bm0-Sp1_BrgA)/Sp1_Lb -> -0.0071106897 | F8: =(Sp1_Bm1-Sp1_BrgA)/Sp1_Lb -> 1.0071107 | G8: =Prof_Kq*Sp1_Lb^2+Sp1_C/3 -> 0.041530915 | H8: =MAX(G8/4,G8*E8*(1-E8),G8*F8*(1-F8)) -> 0.010382729 | I8: =MC1_Net -> 0.12459274 | J8: =C8-I8 -> 0
B9: 2 | C9: =Sp2_C -> 0.56717146 | D9: =Sp2_Lb -> 103.025 | E9: =(Sp2_Bm0-Sp2_BrgA)/Sp2_Lb -> -0.0072797865 | F9: =(Sp2_Bm1-Sp2_BrgA)/Sp2_Lb -> 1.0072798 | G9: =Prof_Kq*Sp2_Lb^2+Sp2_C/3 -> 0.18905715 | H9: =MAX(G9/4,G9*E9*(1-E9),G9*F9*(1-F9)) -> 0.047264289 | I9: =MC2_Net -> 0.56717146 | J9: =C9-I9 -> 0
A11: B. Minimum uncorrected haunch per beam and the common support drop D
B12: Beam | C12: delta min (ft) | D12: Raise (in) | E12: Min haunch with D = 0 (ft) | F12: Min flange haunch (in)
B13: 1-1 | C13: =Bm1_dMin -> -0.12583333 | D13: =Bm1_Raise -> 0 | E13: =C13-Deck_T-D13/12-Bm_D-Sp1_W -> -3.6362161 | F13: =(E13+Sup_Drop)*12 -> 0.94257872
B14: 1-2 | C14: =Bm2_dMin -> -0.12583333 | D14: =Bm2_Raise -> 0 | E14: =C14-Deck_T-D14/12-Bm_D-Sp1_W -> -3.6362161 | F14: =(E14+Sup_Drop)*12 -> 0.94257872
B15: 2-1 | C15: =Bm1_dMin -> -0.12583333 | D15: =Bm1_Raise -> 0 | E15: =C15-Deck_T-D15/12-Bm_D-Sp2_W -> -3.6730976 | F15: =(E15+Sup_Drop)*12 -> 0.5
B16: 2-2 | C16: =Bm2_dMin -> -0.12583333 | D16: =Bm2_Raise -> 0 | E16: =C16-Deck_T-D16/12-Bm_D-Sp2_W -> -3.6730976 | F16: =(E16+Sup_Drop)*12 -> 0.5
B18: Common support drop D (ft) | E18: =Bm_Hmin/12-MIN(E13:E16) -> 3.7147643 | G18: D = h_min,req - min over every beam and flange point of the haunch with D = 0
B19: Minimum flange haunch, whole bridge (in) | E19: =MIN(F13:F16) -> 0.5 | F19: =IF(E19>=Bm_Hmin-0.00000001,"PASS","FAIL") -> PASS
A21: C. Haunch over each beam at the bearings and midspan
B22: Beam | C22: Location | D22: Station s (ft) | E22: t | F22: PGL (ft) | G22: Chord (ft) | H22: Camber (ft) | I22: Beam bottom (ft) | J22: Beam top (ft) | K22: Deck @ CL beam (ft) | L22: Haunch @ CL (in) | M22: Min flange haunch (in)
B23: 1-1 | C23: Begin brg | D23: =Sp1_BrgA -> 1594.22 | E23: =(D23-Sp1_BrgA)/Sp1_Lb -> 0 | F23: =IF(Prof_Mode="parabolic",Prof_Z0+Prof_G1*((D23)-Prof_Sta0)+Prof_Kq*((D23)-Prof_Sta0)^2,IF((D23)<=Prof_PISta,Prof_Z0+Prof_G1*((D23)-Prof_Sta0),Prof_PIZ+Prof_G2*((D23)-Prof_PISta))) -> 47.665999 | G23: =Sp1_ZA+(Sp1_ZB-Sp1_ZA)*E23 -> 47.665999 | H23: =Sp1_C/3*E23*(1-E23) -> 0 | I23: =G23-Sup_Drop+H23+Bm1_Raise/12 -> 43.951235 | J23: =I23+Bm_D -> 46.951235 | K23: =F23+Bm1_dCL -> 47.580166 | L23: =(K23-Deck_T-J23)*12 -> 1.5471715 | M23: =(F23+Bm1_dMin-Deck_T-J23)*12 -> 1.0671715
B24: 1-1 | C24: Midspan | D24: =Sp1_Mid -> 1646.9575 | E24: =(D24-Sp1_BrgA)/Sp1_Lb -> 0.5 | F24: =IF(Prof_Mode="parabolic",Prof_Z0+Prof_G1*((D24)-Prof_Sta0)+Prof_Kq*((D24)-Prof_Sta0)^2,IF((D24)<=Prof_PISta,Prof_Z0+Prof_G1*((D24)-Prof_Sta0),Prof_PIZ+Prof_G2*((D24)-Prof_PISta))) -> 47.929625 | G24: =Sp1_ZA+(Sp1_ZB-Sp1_ZA)*E24 -> 47.929625 | H24: =Sp1_C/3*E24*(1-E24) -> 0.010382729 | I24: =G24-Sup_Drop+H24+Bm1_Raise/12 -> 44.225243 | J24: =I24+Bm_D -> 47.225243 | K24: =F24+Bm1_dCL -> 47.843792 | L24: =(K24-Deck_T-J24)*12 -> 1.4225787 | M24: =(F24+Bm1_dMin-Deck_T-J24)*12 -> 0.94257872
B25: 1-1 | C25: End brg | D25: =Sp1_BrgB -> 1699.695 | E25: =(D25-Sp1_BrgA)/Sp1_Lb -> 1 | F25: =IF(Prof_Mode="parabolic",Prof_Z0+Prof_G1*((D25)-Prof_Sta0)+Prof_Kq*((D25)-Prof_Sta0)^2,IF((D25)<=Prof_PISta,Prof_Z0+Prof_G1*((D25)-Prof_Sta0),Prof_PIZ+Prof_G2*((D25)-Prof_PISta))) -> 48.193251 | G25: =Sp1_ZA+(Sp1_ZB-Sp1_ZA)*E25 -> 48.193251 | H25: =Sp1_C/3*E25*(1-E25) -> 0 | I25: =G25-Sup_Drop+H25+Bm1_Raise/12 -> 44.478487 | J25: =I25+Bm_D -> 47.478487 | K25: =F25+Bm1_dCL -> 48.107418 | L25: =(K25-Deck_T-J25)*12 -> 1.5471715 | M25: =(F25+Bm1_dMin-Deck_T-J25)*12 -> 1.0671715
B26: 1-2 | C26: Begin brg | D26: =Sp1_BrgA -> 1594.22 | E26: =(D26-Sp1_BrgA)/Sp1_Lb -> 0 | F26: =IF(Prof_Mode="parabolic",Prof_Z0+Prof_G1*((D26)-Prof_Sta0)+Prof_Kq*((D26)-Prof_Sta0)^2,IF((D26)<=Prof_PISta,Prof_Z0+Prof_G1*((D26)-Prof_Sta0),Prof_PIZ+Prof_G2*((D26)-Prof_PISta))) -> 47.665999 | G26: =Sp1_ZA+(Sp1_ZB-Sp1_ZA)*E26 -> 47.665999 | H26: =Sp1_C/3*E26*(1-E26) -> 0 | I26: =G26-Sup_Drop+H26+Bm2_Raise/12 -> 43.951235 | J26: =I26+Bm_D -> 46.951235 | K26: =F26+Bm2_dCL -> 47.580166 | L26: =(K26-Deck_T-J26)*12 -> 1.5471715 | M26: =(F26+Bm2_dMin-Deck_T-J26)*12 -> 1.0671715
B27: 1-2 | C27: Midspan | D27: =Sp1_Mid -> 1646.9575 | E27: =(D27-Sp1_BrgA)/Sp1_Lb -> 0.5 | F27: =IF(Prof_Mode="parabolic",Prof_Z0+Prof_G1*((D27)-Prof_Sta0)+Prof_Kq*((D27)-Prof_Sta0)^2,IF((D27)<=Prof_PISta,Prof_Z0+Prof_G1*((D27)-Prof_Sta0),Prof_PIZ+Prof_G2*((D27)-Prof_PISta))) -> 47.929625 | G27: =Sp1_ZA+(Sp1_ZB-Sp1_ZA)*E27 -> 47.929625 | H27: =Sp1_C/3*E27*(1-E27) -> 0.010382729 | I27: =G27-Sup_Drop+H27+Bm2_Raise/12 -> 44.225243 | J27: =I27+Bm_D -> 47.225243 | K27: =F27+Bm2_dCL -> 47.843792 | L27: =(K27-Deck_T-J27)*12 -> 1.4225787 | M27: =(F27+Bm2_dMin-Deck_T-J27)*12 -> 0.94257872
B28: 1-2 | C28: End brg | D28: =Sp1_BrgB -> 1699.695 | E28: =(D28-Sp1_BrgA)/Sp1_Lb -> 1 | F28: =IF(Prof_Mode="parabolic",Prof_Z0+Prof_G1*((D28)-Prof_Sta0)+Prof_Kq*((D28)-Prof_Sta0)^2,IF((D28)<=Prof_PISta,Prof_Z0+Prof_G1*((D28)-Prof_Sta0),Prof_PIZ+Prof_G2*((D28)-Prof_PISta))) -> 48.193251 | G28: =Sp1_ZA+(Sp1_ZB-Sp1_ZA)*E28 -> 48.193251 | H28: =Sp1_C/3*E28*(1-E28) -> 0 | I28: =G28-Sup_Drop+H28+Bm2_Raise/12 -> 44.478487 | J28: =I28+Bm_D -> 47.478487 | K28: =F28+Bm2_dCL -> 48.107418 | L28: =(K28-Deck_T-J28)*12 -> 1.5471715 | M28: =(F28+Bm2_dMin-Deck_T-J28)*12 -> 1.0671715
B29: 2-1 | C29: Begin brg | D29: =Sp2_BrgA -> 1701.445 | E29: =(D29-Sp2_BrgA)/Sp2_Lb -> 0 | F29: =IF(Prof_Mode="parabolic",Prof_Z0+Prof_G1*((D29)-Prof_Sta0)+Prof_Kq*((D29)-Prof_Sta0)^2,IF((D29)<=Prof_PISta,Prof_Z0+Prof_G1*((D29)-Prof_Sta0),Prof_PIZ+Prof_G2*((D29)-Prof_PISta))) -> 48.193249 | G29: =Sp2_ZA+(Sp2_ZB-Sp2_ZA)*E29 -> 48.193249 | H29: =Sp2_C/3*E29*(1-E29) -> 0 | I29: =G29-Sup_Drop+H29+Bm1_Raise/12 -> 44.478485 | J29: =I29+Bm_D -> 47.478485 | K29: =F29+Bm1_dCL -> 48.107416 | L29: =(K29-Deck_T-J29)*12 -> 1.5471715 | M29: =(F29+Bm1_dMin-Deck_T-J29)*12 -> 1.0671715
B30: 2-1 | C30: Midspan | D30: =Sp2_Mid -> 1752.9575 | E30: =(D30-Sp2_BrgA)/Sp2_Lb -> 0.5 | F30: =IF(Prof_Mode="parabolic",Prof_Z0+Prof_G1*((D30)-Prof_Sta0)+Prof_Kq*((D30)-Prof_Sta0)^2,IF((D30)<=Prof_PISta,Prof_Z0+Prof_G1*((D30)-Prof_Sta0),Prof_PIZ+Prof_G2*((D30)-Prof_PISta))) -> 47.935625 | G30: =Sp2_ZA+(Sp2_ZB-Sp2_ZA)*E30 -> 47.935625 | H30: =Sp2_C/3*E30*(1-E30) -> 0.047264289 | I30: =G30-Sup_Drop+H30+Bm1_Raise/12 -> 44.268125 | J30: =I30+Bm_D -> 47.268125 | K30: =F30+Bm1_dCL -> 47.849792 | L30: =(K30-Deck_T-J30)*12 -> 0.98 | M30: =(F30+Bm1_dMin-Deck_T-J30)*12 -> 0.5
B31: 2-1 | C31: End brg | D31: =Sp2_BrgB -> 1804.47 | E31: =(D31-Sp2_BrgA)/Sp2_Lb -> 1 | F31: =IF(Prof_Mode="parabolic",Prof_Z0+Prof_G1*((D31)-Prof_Sta0)+Prof_Kq*((D31)-Prof_Sta0)^2,IF((D31)<=Prof_PISta,Prof_Z0+Prof_G1*((D31)-Prof_Sta0),Prof_PIZ+Prof_G2*((D31)-Prof_PISta))) -> 47.678001 | G31: =Sp2_ZA+(Sp2_ZB-Sp2_ZA)*E31 -> 47.678001 | H31: =Sp2_C/3*E31*(1-E31) -> 0 | I31: =G31-Sup_Drop+H31+Bm1_Raise/12 -> 43.963237 | J31: =I31+Bm_D -> 46.963237 | K31: =F31+Bm1_dCL -> 47.592168 | L31: =(K31-Deck_T-J31)*12 -> 1.5471715 | M31: =(F31+Bm1_dMin-Deck_T-J31)*12 -> 1.0671715
B32: 2-2 | C32: Begin brg | D32: =Sp2_BrgA -> 1701.445 | E32: =(D32-Sp2_BrgA)/Sp2_Lb -> 0 | F32: =IF(Prof_Mode="parabolic",Prof_Z0+Prof_G1*((D32)-Prof_Sta0)+Prof_Kq*((D32)-Prof_Sta0)^2,IF((D32)<=Prof_PISta,Prof_Z0+Prof_G1*((D32)-Prof_Sta0),Prof_PIZ+Prof_G2*((D32)-Prof_PISta))) -> 48.193249 | G32: =Sp2_ZA+(Sp2_ZB-Sp2_ZA)*E32 -> 48.193249 | H32: =Sp2_C/3*E32*(1-E32) -> 0 | I32: =G32-Sup_Drop+H32+Bm2_Raise/12 -> 44.478485 | J32: =I32+Bm_D -> 47.478485 | K32: =F32+Bm2_dCL -> 48.107416 | L32: =(K32-Deck_T-J32)*12 -> 1.5471715 | M32: =(F32+Bm2_dMin-Deck_T-J32)*12 -> 1.0671715
B33: 2-2 | C33: Midspan | D33: =Sp2_Mid -> 1752.9575 | E33: =(D33-Sp2_BrgA)/Sp2_Lb -> 0.5 | F33: =IF(Prof_Mode="parabolic",Prof_Z0+Prof_G1*((D33)-Prof_Sta0)+Prof_Kq*((D33)-Prof_Sta0)^2,IF((D33)<=Prof_PISta,Prof_Z0+Prof_G1*((D33)-Prof_Sta0),Prof_PIZ+Prof_G2*((D33)-Prof_PISta))) -> 47.935625 | G33: =Sp2_ZA+(Sp2_ZB-Sp2_ZA)*E33 -> 47.935625 | H33: =Sp2_C/3*E33*(1-E33) -> 0.047264289 | I33: =G33-Sup_Drop+H33+Bm2_Raise/12 -> 44.268125 | J33: =I33+Bm_D -> 47.268125 | K33: =F33+Bm2_dCL -> 47.849792 | L33: =(K33-Deck_T-J33)*12 -> 0.98 | M33: =(F33+Bm2_dMin-Deck_T-J33)*12 -> 0.5
B34: 2-2 | C34: End brg | D34: =Sp2_BrgB -> 1804.47 | E34: =(D34-Sp2_BrgA)/Sp2_Lb -> 1 | F34: =IF(Prof_Mode="parabolic",Prof_Z0+Prof_G1*((D34)-Prof_Sta0)+Prof_Kq*((D34)-Prof_Sta0)^2,IF((D34)<=Prof_PISta,Prof_Z0+Prof_G1*((D34)-Prof_Sta0),Prof_PIZ+Prof_G2*((D34)-Prof_PISta))) -> 47.678001 | G34: =Sp2_ZA+(Sp2_ZB-Sp2_ZA)*E34 -> 47.678001 | H34: =Sp2_C/3*E34*(1-E34) -> 0 | I34: =G34-Sup_Drop+H34+Bm2_Raise/12 -> 43.963237 | J34: =I34+Bm_D -> 46.963237 | K34: =F34+Bm2_dCL -> 47.592168 | L34: =(K34-Deck_T-J34)*12 -> 1.5471715 | M34: =(F34+Bm2_dMin-Deck_T-J34)*12 -> 1.0671715
A36: D. Build-up summary (FDOT Build-Up & Deflection table)
B37: Beam | C37: Dim B begin (in) | D37: Dim C CL span (in) | E37: Dim D end (in) | F37: Mid-ordinate R (in) | G37: Net camber C (in) | H37: Build-up case
B38: 1-1 | C38: =L23 -> 1.5471715 | D38: =L24 -> 1.4225787 | E38: =L25 -> 1.5471715 | F38: =(K24-(K23+K25)/2)*12 -> 0 | G38: =Sp1_C -> 0.12459274 | H38: =IF(ROUND(F38,6)<0,"Case 2",IF(ROUND(F38,6)>G38,"Case 4",IF(ROUND(F38,6)>0,"Case 3","Case 1"))) -> Case 1
B39: 1-2 | C39: =L26 -> 1.5471715 | D39: =L27 -> 1.4225787 | E39: =L28 -> 1.5471715 | F39: =(K27-(K26+K28)/2)*12 -> 0 | G39: =Sp1_C -> 0.12459274 | H39: =IF(ROUND(F39,6)<0,"Case 2",IF(ROUND(F39,6)>G39,"Case 4",IF(ROUND(F39,6)>0,"Case 3","Case 1"))) -> Case 1
B40: 2-1 | C40: =L29 -> 1.5471715 | D40: =L30 -> 0.98 | E40: =L31 -> 1.5471715 | F40: =(K30-(K29+K31)/2)*12 -> 8.5265128e-14 | G40: =Sp2_C -> 0.56717146 | H40: =IF(ROUND(F40,6)<0,"Case 2",IF(ROUND(F40,6)>G40,"Case 4",IF(ROUND(F40,6)>0,"Case 3","Case 1"))) -> Case 1
B41: 2-2 | C41: =L32 -> 1.5471715 | D41: =L33 -> 0.98 | E41: =L34 -> 1.5471715 | F41: =(K33-(K32+K34)/2)*12 -> 8.5265128e-14 | G41: =Sp2_C -> 0.56717146 | H41: =IF(ROUND(F41,6)<0,"Case 2",IF(ROUND(F41,6)>G41,"Case 4",IF(ROUND(F41,6)>0,"Case 3","Case 1"))) -> Case 1
A43: E. Mathcad deflections by span (in, + up)
B44: Span | C44: Release (max) | D44: 120 day (max) | E44: Non-comp. DL (min) | F44: Composite DL (min) | G44: Sum = NetCamber | H44: Mathcad NetCamber | I44: CONFIG camber | J44: Check
B45: 1 | C45: =MC1_Drel -> 1.3711622 | D45: =MC1_D120 -> 3.3554493 | E45: =MC1_Dnc -> -2.471606 | F45: =MC1_Dc -> -0.75925047 | G45: =D45+E45+F45 -> 0.12459274 | H45: =MC1_Net -> 0.12459274 | I45: =Sp1_C -> 0.12459274 | J45: =IF(AND(ABS(G45-H45)<0.000000001,ABS(H45-I45)<0.000000001),"PASS","FAIL") -> PASS
B46: 2 | C46: =MC2_Drel -> 1.4647226 | D46: =MC2_D120 -> 3.5081218 | E46: =MC2_Dnc -> -2.2498277 | F46: =MC2_Dc -> -0.69112259 | G46: =D46+E46+F46 -> 0.56717146 | H46: =MC2_Net -> 0.56717146 | I46: =Sp2_C -> 0.56717146 | J46: =IF(AND(ABS(G46-H46)<0.000000001,ABS(H46-I46)<0.000000001),"PASS","FAIL") -> PASS

Sheet Camber & Haunch Method
B1: Camber & Haunch - Method
B2: Common support drop D, build-up dimensions and the minimum haunch
B5: 1. Beam soffit with camber
B6: Within a span, t runs from 0 at bearing A to 1 at bearing B. The soffit follows the PGL chord between bearings, dropped by one common distance D for every support, plus the Mathcad camber as an upward parabola and any entered beam raise r:
B14: 2. Haunch and the exact minimum
B18: Because the PGL is straight (brokeback) or a single parabola over each beam, z_PGL - q is itself -k_q L_b^2 t(1-t). The haunch over a beam is therefore an exact quadratic in t, and its minimum on the beam (t from t_lo to t_hi) has a closed form:
B25: t = 1/2 always lies on the beam, so m/4 covers upward camber; the end terms cover a net sag. The notebook finds the same minimum by locating every quadratic extremum between breakpoints. One common drop then enforces the required minimum haunch everywhere:
B29: Current: D = 3.7147642886 ft. The minimum flange haunch 0.500000 in (required 0.5 in) occurs on beam 1 at 17+52.96.
B48: Figure 1. Span 2 (larger camber, governs D). Vertical scale exaggerated about the bearing chord.
B67: Figure 2. Span 1 has less camber, so with the common drop its midspan haunch is larger.
B69: 3. Build-up dimensions and case
B70: Dims B, C and D are the haunch over the beam centerline at the begin bearing, midspan and end bearing. The build-up case follows the BCC template rule using the vertical-curve mid-ordinate of the FGE over the beam centerline:
B74: A straight PGL in each span gives R_m = 0, so every beam is Case 1.
B75: Symbol | C75: Meaning | H75: Workbook name / location | K75: Units / value
B76: C | C76: Net camber (Mathcad NetCamber) | H76: Sp1_C, Sp2_C | K76: in
B77: D | C77: Common support drop | H77: Sup_Drop | K77: ft
B78: td, db, hreq | C78: Deck thickness, beam depth, minimum haunch | H78: Deck_T, Bm_D, Bm_Hmin | K78: ft, ft, in
B79: m, W | C79: Haunch curvature term and its maximum on the beam | H79: Sp1_m, Sp1_W ... | K79: ft
B80: B, C, D dims | C80: Build-up over CL beam at begin, mid, end | H80: Camber & Haunch section D | K80: in

Sheet FGE
A1: Finished Grade Elevations | N1: Project | O1: =""&TB_Project -> D2 I-95 Pedestrian Bridge
A2: FGE = PGL(s) + delta(y) at every line and station (top of deck) | N2: Job No. | O2: =""&TB_JobNo
N3: Calc. by / date | O3: =TB_CalcBy&" "&TB_CalcDate
N4: Check. by / date | O4: =TB_CheckBy&" "&TB_CheckDate
A6: Span 1
B7: Location | C7: Offset y (ft) | D7: delta(y) (ft) | E7: FFBW EB 1 | F7: CL Brg | G7: 1 | H7: 2 | I7: 3 | J7: 4 | K7: 5 | L7: 6 | M7: 7 | N7: 8 | O7: 9 | P7: CL Brg | Q7: CL Pier
B8: Station (ft) | E8: =Sp1_Sta0 -> 1593.22 | F8: =Sp1_BrgA -> 1594.22 | G8: =Sp1_BrgA+1*Sp1_Lb/Des_FGEInc -> 1604.7675 | H8: =Sp1_BrgA+2*Sp1_Lb/Des_FGEInc -> 1615.315 | I8: =Sp1_BrgA+3*Sp1_Lb/Des_FGEInc -> 1625.8625 | J8: =Sp1_BrgA+4*Sp1_Lb/Des_FGEInc -> 1636.41 | K8: =Sp1_BrgA+5*Sp1_Lb/Des_FGEInc -> 1646.9575 | L8: =Sp1_BrgA+6*Sp1_Lb/Des_FGEInc -> 1657.505 | M8: =Sp1_BrgA+7*Sp1_Lb/Des_FGEInc -> 1668.0525 | N8: =Sp1_BrgA+8*Sp1_Lb/Des_FGEInc -> 1678.6 | O8: =Sp1_BrgA+9*Sp1_Lb/Des_FGEInc -> 1689.1475 | P8: =Sp1_BrgB -> 1699.695 | Q8: =Sp1_Sta1 -> 1700.57
B9: Station label | E9: =TEXT(INT(ROUND(E8*100,0)/10000),"0")&"+"&TEXT(MOD(ROUND(E8*100,0),10000)/100,"00.00") -> 15+93.22 | F9: =TEXT(INT(ROUND(F8*100,0)/10000),"0")&"+"&TEXT(MOD(ROUND(F8*100,0),10000)/100,"00.00") -> 15+94.22 | G9: =TEXT(INT(ROUND(G8*100,0)/10000),"0")&"+"&TEXT(MOD(ROUND(G8*100,0),10000)/100,"00.00") -> 16+04.77 | H9: =TEXT(INT(ROUND(H8*100,0)/10000),"0")&"+"&TEXT(MOD(ROUND(H8*100,0),10000)/100,"00.00") -> 16+15.32 | I9: =TEXT(INT(ROUND(I8*100,0)/10000),"0")&"+"&TEXT(MOD(ROUND(I8*100,0),10000)/100,"00.00") -> 16+25.86 | J9: =TEXT(INT(ROUND(J8*100,0)/10000),"0")&"+"&TEXT(MOD(ROUND(J8*100,0),10000)/100,"00.00") -> 16+36.41 | K9: =TEXT(INT(ROUND(K8*100,0)/10000),"0")&"+"&TEXT(MOD(ROUND(K8*100,0),10000)/100,"00.00") -> 16+46.96 | L9: =TEXT(INT(ROUND(L8*100,0)/10000),"0")&"+"&TEXT(MOD(ROUND(L8*100,0),10000)/100,"00.00") -> 16+57.51 | ... Q9: =TEXT(INT(ROUND(Q8*100,0)/10000),"0")&"+"&TEXT(MOD(ROUND(Q8*100,0),10000)/100,"00.00") -> 17+00.57
B10: Deck present? | E10: =IF(AND(E8>=Sp1_Dk0-0.000000001,E8<=Sp1_Dk1+0.000000001),"deck","PGL ext.") -> PGL ext. | F10: =IF(AND(F8>=Sp1_Dk0-0.000000001,F8<=Sp1_Dk1+0.000000001),"deck","PGL ext.") -> deck | G10: =IF(AND(G8>=Sp1_Dk0-0.000000001,G8<=Sp1_Dk1+0.000000001),"deck","PGL ext.") -> deck | H10: =IF(AND(H8>=Sp1_Dk0-0.000000001,H8<=Sp1_Dk1+0.000000001),"deck","PGL ext.") -> deck | I10: =IF(AND(I8>=Sp1_Dk0-0.000000001,I8<=Sp1_Dk1+0.000000001),"deck","PGL ext.") -> deck | J10: =IF(AND(J8>=Sp1_Dk0-0.000000001,J8<=Sp1_Dk1+0.000000001),"deck","PGL ext.") -> deck | K10: =IF(AND(K8>=Sp1_Dk0-0.000000001,K8<=Sp1_Dk1+0.000000001),"deck","PGL ext.") -> deck | L10: =IF(AND(L8>=Sp1_Dk0-0.000000001,L8<=Sp1_Dk1+0.000000001),"deck","PGL ext.") -> deck | ... Q10: =IF(AND(Q8>=Sp1_Dk0-0.000000001,Q8<=Sp1_Dk1+0.000000001),"deck","PGL ext.") -> deck
B11: PGL elevation (ft) | E11: =IF(Prof_Mode="parabolic",Prof_Z0+Prof_G1*((E8)-Prof_Sta0)+Prof_Kq*((E8)-Prof_Sta0)^2,IF((E8)<=Prof_PISta,Prof_Z0+Prof_G1*((E8)-Prof_Sta0),Prof_PIZ+Prof_G2*((E8)-Prof_PISta))) -> 47.661 | F11: =IF(Prof_Mode="parabolic",Prof_Z0+Prof_G1*((F8)-Prof_Sta0)+Prof_Kq*((F8)-Prof_Sta0)^2,IF((F8)<=Prof_PISta,Prof_Z0+Prof_G1*((F8)-Prof_Sta0),Prof_PIZ+Prof_G2*((F8)-Prof_PISta))) -> 47.665999 | G11: =IF(Prof_Mode="parabolic",Prof_Z0+Prof_G1*((G8)-Prof_Sta0)+Prof_Kq*((G8)-Prof_Sta0)^2,IF((G8)<=Prof_PISta,Prof_Z0+Prof_G1*((G8)-Prof_Sta0),Prof_PIZ+Prof_G2*((G8)-Prof_PISta))) -> 47.718724 | H11: =IF(Prof_Mode="parabolic",Prof_Z0+Prof_G1*((H8)-Prof_Sta0)+Prof_Kq*((H8)-Prof_Sta0)^2,IF((H8)<=Prof_PISta,Prof_Z0+Prof_G1*((H8)-Prof_Sta0),Prof_PIZ+Prof_G2*((H8)-Prof_PISta))) -> 47.771449 | I11: =IF(Prof_Mode="parabolic",Prof_Z0+Prof_G1*((I8)-Prof_Sta0)+Prof_Kq*((I8)-Prof_Sta0)^2,IF((I8)<=Prof_PISta,Prof_Z0+Prof_G1*((I8)-Prof_Sta0),Prof_PIZ+Prof_G2*((I8)-Prof_PISta))) -> 47.824174 | J11: =IF(Prof_Mode="parabolic",Prof_Z0+Prof_G1*((J8)-Prof_Sta0)+Prof_Kq*((J8)-Prof_Sta0)^2,IF((J8)<=Prof_PISta,Prof_Z0+Prof_G1*((J8)-Prof_Sta0),Prof_PIZ+Prof_G2*((J8)-Prof_PISta))) -> 47.8769 | K11: =IF(Prof_Mode="parabolic",Prof_Z0+Prof_G1*((K8)-Prof_Sta0)+Prof_Kq*((K8)-Prof_Sta0)^2,IF((K8)<=Prof_PISta,Prof_Z0+Prof_G1*((K8)-Prof_Sta0),Prof_PIZ+Prof_G2*((K8)-Prof_PISta))) -> 47.929625 | L11: =IF(Prof_Mode="parabolic",Prof_Z0+Prof_G1*((L8)-Prof_Sta0)+Prof_Kq*((L8)-Prof_Sta0)^2,IF((L8)<=Prof_PISta,Prof_Z0+Prof_G1*((L8)-Prof_Sta0),Prof_PIZ+Prof_G2*((L8)-Prof_PISta))) -> 47.98235 | ... Q11: =IF(Prof_Mode="parabolic",Prof_Z0+Prof_G1*((Q8)-Prof_Sta0)+Prof_Kq*((Q8)-Prof_Sta0)^2,IF((Q8)<=Prof_PISta,Prof_Z0+Prof_G1*((Q8)-Prof_Sta0),Prof_PIZ+Prof_G2*((Q8)-Prof_PISta))) -> 48.197625
B12: Left coping (deck edge) | C12: =Deck_YL -> -6.7916667 | D12: =IF(Deck_Mode="uniform",Deck_Uni*(C12),Deck_Crown*ABS(C12)) -> -0.13583333 | E12: =E$11+$D12 -> 47.525167 | F12: =F$11+$D12 -> 47.530166 | G12: =G$11+$D12 -> 47.582891 | H12: =H$11+$D12 -> 47.635616 | I12: =I$11+$D12 -> 47.688341 | J12: =J$11+$D12 -> 47.741066 | K12: =K$11+$D12 -> 47.793792 | L12: =L$11+$D12 -> 47.846517 | ... Q12: =Q$11+$D12 -> 48.061792
B13: CL Beam 1-1 | C13: =Bm1_Off -> -4.2916667 | D13: =IF(Deck_Mode="uniform",Deck_Uni*(C13),Deck_Crown*ABS(C13)) -> -0.085833333 | E13: =E$11+$D13 -> 47.575167 | F13: =F$11+$D13 -> 47.580166 | G13: =G$11+$D13 -> 47.632891 | H13: =H$11+$D13 -> 47.685616 | I13: =I$11+$D13 -> 47.738341 | J13: =J$11+$D13 -> 47.791066 | K13: =K$11+$D13 -> 47.843792 | L13: =L$11+$D13 -> 47.896517 | ... Q13: =Q$11+$D13 -> 48.111792
B14: PGL | C14: 0 | D14: =IF(Deck_Mode="uniform",Deck_Uni*(C14),Deck_Crown*ABS(C14)) -> 0 | E14: =E$11+$D14 -> 47.661 | F14: =F$11+$D14 -> 47.665999 | G14: =G$11+$D14 -> 47.718724 | H14: =H$11+$D14 -> 47.771449 | I14: =I$11+$D14 -> 47.824174 | J14: =J$11+$D14 -> 47.8769 | K14: =K$11+$D14 -> 47.929625 | L14: =L$11+$D14 -> 47.98235 | ... Q14: =Q$11+$D14 -> 48.197625
B15: CL Beam 1-2 | C15: =Bm2_Off -> 4.2916667 | D15: =IF(Deck_Mode="uniform",Deck_Uni*(C15),Deck_Crown*ABS(C15)) -> -0.085833333 | E15: =E$11+$D15 -> 47.575167 | F15: =F$11+$D15 -> 47.580166 | G15: =G$11+$D15 -> 47.632891 | H15: =H$11+$D15 -> 47.685616 | I15: =I$11+$D15 -> 47.738341 | J15: =J$11+$D15 -> 47.791066 | K15: =K$11+$D15 -> 47.843792 | L15: =L$11+$D15 -> 47.896517 | ... Q15: =Q$11+$D15 -> 48.111792
B16: Right coping (deck edge) | C16: =Deck_YR -> 6.7916667 | D16: =IF(Deck_Mode="uniform",Deck_Uni*(C16),Deck_Crown*ABS(C16)) -> -0.13583333 | E16: =E$11+$D16 -> 47.525167 | F16: =F$11+$D16 -> 47.530166 | G16: =G$11+$D16 -> 47.582891 | H16: =H$11+$D16 -> 47.635616 | I16: =I$11+$D16 -> 47.688341 | J16: =J$11+$D16 -> 47.741066 | K16: =K$11+$D16 -> 47.793792 | L16: =L$11+$D16 -> 47.846517 | ... Q16: =Q$11+$D16 -> 48.061792
B17: Increment (ft) | C17: =Sp1_Lb/Des_FGEInc -> 10.5475
A19: Span 2
B20: Location | C20: Offset y (ft) | D20: delta(y) (ft) | E20: CL Pier | F20: CL Brg | G20: 1 | H20: 2 | I20: 3 | J20: 4 | K20: 5 | L20: 6 | M20: 7 | N20: 8 | O20: 9 | P20: CL Brg | Q20: FFBW EB 2
B21: Station (ft) | E21: =Sp2_Sta0 -> 1700.57 | F21: =Sp2_BrgA -> 1701.445 | G21: =Sp2_BrgA+1*Sp2_Lb/Des_FGEInc -> 1711.7475 | H21: =Sp2_BrgA+2*Sp2_Lb/Des_FGEInc -> 1722.05 | I21: =Sp2_BrgA+3*Sp2_Lb/Des_FGEInc -> 1732.3525 | J21: =Sp2_BrgA+4*Sp2_Lb/Des_FGEInc -> 1742.655 | K21: =Sp2_BrgA+5*Sp2_Lb/Des_FGEInc -> 1752.9575 | L21: =Sp2_BrgA+6*Sp2_Lb/Des_FGEInc -> 1763.26 | M21: =Sp2_BrgA+7*Sp2_Lb/Des_FGEInc -> 1773.5625 | N21: =Sp2_BrgA+8*Sp2_Lb/Des_FGEInc -> 1783.865 | O21: =Sp2_BrgA+9*Sp2_Lb/Des_FGEInc -> 1794.1675 | P21: =Sp2_BrgB -> 1804.47 | Q21: =Sp2_Sta1 -> 1805.47
B22: Station label | E22: =TEXT(INT(ROUND(E21*100,0)/10000),"0")&"+"&TEXT(MOD(ROUND(E21*100,0),10000)/100,"00.00") -> 17+00.57 | F22: =TEXT(INT(ROUND(F21*100,0)/10000),"0")&"+"&TEXT(MOD(ROUND(F21*100,0),10000)/100,"00.00") -> 17+01.45 | G22: =TEXT(INT(ROUND(G21*100,0)/10000),"0")&"+"&TEXT(MOD(ROUND(G21*100,0),10000)/100,"00.00") -> 17+11.75 | H22: =TEXT(INT(ROUND(H21*100,0)/10000),"0")&"+"&TEXT(MOD(ROUND(H21*100,0),10000)/100,"00.00") -> 17+22.05 | I22: =TEXT(INT(ROUND(I21*100,0)/10000),"0")&"+"&TEXT(MOD(ROUND(I21*100,0),10000)/100,"00.00") -> 17+32.35 | J22: =TEXT(INT(ROUND(J21*100,0)/10000),"0")&"+"&TEXT(MOD(ROUND(J21*100,0),10000)/100,"00.00") -> 17+42.66 | K22: =TEXT(INT(ROUND(K21*100,0)/10000),"0")&"+"&TEXT(MOD(ROUND(K21*100,0),10000)/100,"00.00") -> 17+52.96 | L22: =TEXT(INT(ROUND(L21*100,0)/10000),"0")&"+"&TEXT(MOD(ROUND(L21*100,0),10000)/100,"00.00") -> 17+63.26 | ... Q22: =TEXT(INT(ROUND(Q21*100,0)/10000),"0")&"+"&TEXT(MOD(ROUND(Q21*100,0),10000)/100,"00.00") -> 18+05.47
B23: Deck present? | E23: =IF(AND(E21>=Sp2_Dk0-0.000000001,E21<=Sp2_Dk1+0.000000001),"deck","PGL ext.") -> deck | F23: =IF(AND(F21>=Sp2_Dk0-0.000000001,F21<=Sp2_Dk1+0.000000001),"deck","PGL ext.") -> deck | G23: =IF(AND(G21>=Sp2_Dk0-0.000000001,G21<=Sp2_Dk1+0.000000001),"deck","PGL ext.") -> deck | H23: =IF(AND(H21>=Sp2_Dk0-0.000000001,H21<=Sp2_Dk1+0.000000001),"deck","PGL ext.") -> deck | I23: =IF(AND(I21>=Sp2_Dk0-0.000000001,I21<=Sp2_Dk1+0.000000001),"deck","PGL ext.") -> deck | J23: =IF(AND(J21>=Sp2_Dk0-0.000000001,J21<=Sp2_Dk1+0.000000001),"deck","PGL ext.") -> deck | K23: =IF(AND(K21>=Sp2_Dk0-0.000000001,K21<=Sp2_Dk1+0.000000001),"deck","PGL ext.") -> deck | L23: =IF(AND(L21>=Sp2_Dk0-0.000000001,L21<=Sp2_Dk1+0.000000001),"deck","PGL ext.") -> deck | ... Q23: =IF(AND(Q21>=Sp2_Dk0-0.000000001,Q21<=Sp2_Dk1+0.000000001),"deck","PGL ext.") -> PGL ext.
B24: PGL elevation (ft) | E24: =IF(Prof_Mode="parabolic",Prof_Z0+Prof_G1*((E21)-Prof_Sta0)+Prof_Kq*((E21)-Prof_Sta0)^2,IF((E21)<=Prof_PISta,Prof_Z0+Prof_G1*((E21)-Prof_Sta0),Prof_PIZ+Prof_G2*((E21)-Prof_PISta))) -> 48.197625 | F24: =IF(Prof_Mode="parabolic",Prof_Z0+Prof_G1*((F21)-Prof_Sta0)+Prof_Kq*((F21)-Prof_Sta0)^2,IF((F21)<=Prof_PISta,Prof_Z0+Prof_G1*((F21)-Prof_Sta0),Prof_PIZ+Prof_G2*((F21)-Prof_PISta))) -> 48.193249 | G24: =IF(Prof_Mode="parabolic",Prof_Z0+Prof_G1*((G21)-Prof_Sta0)+Prof_Kq*((G21)-Prof_Sta0)^2,IF((G21)<=Prof_PISta,Prof_Z0+Prof_G1*((G21)-Prof_Sta0),Prof_PIZ+Prof_G2*((G21)-Prof_PISta))) -> 48.141724 | H24: =IF(Prof_Mode="parabolic",Prof_Z0+Prof_G1*((H21)-Prof_Sta0)+Prof_Kq*((H21)-Prof_Sta0)^2,IF((H21)<=Prof_PISta,Prof_Z0+Prof_G1*((H21)-Prof_Sta0),Prof_PIZ+Prof_G2*((H21)-Prof_PISta))) -> 48.090199 | I24: =IF(Prof_Mode="parabolic",Prof_Z0+Prof_G1*((I21)-Prof_Sta0)+Prof_Kq*((I21)-Prof_Sta0)^2,IF((I21)<=Prof_PISta,Prof_Z0+Prof_G1*((I21)-Prof_Sta0),Prof_PIZ+Prof_G2*((I21)-Prof_PISta))) -> 48.038675 | J24: =IF(Prof_Mode="parabolic",Prof_Z0+Prof_G1*((J21)-Prof_Sta0)+Prof_Kq*((J21)-Prof_Sta0)^2,IF((J21)<=Prof_PISta,Prof_Z0+Prof_G1*((J21)-Prof_Sta0),Prof_PIZ+Prof_G2*((J21)-Prof_PISta))) -> 47.98715 | K24: =IF(Prof_Mode="parabolic",Prof_Z0+Prof_G1*((K21)-Prof_Sta0)+Prof_Kq*((K21)-Prof_Sta0)^2,IF((K21)<=Prof_PISta,Prof_Z0+Prof_G1*((K21)-Prof_Sta0),Prof_PIZ+Prof_G2*((K21)-Prof_PISta))) -> 47.935625 | L24: =IF(Prof_Mode="parabolic",Prof_Z0+Prof_G1*((L21)-Prof_Sta0)+Prof_Kq*((L21)-Prof_Sta0)^2,IF((L21)<=Prof_PISta,Prof_Z0+Prof_G1*((L21)-Prof_Sta0),Prof_PIZ+Prof_G2*((L21)-Prof_PISta))) -> 47.8841 | ... Q24: =IF(Prof_Mode="parabolic",Prof_Z0+Prof_G1*((Q21)-Prof_Sta0)+Prof_Kq*((Q21)-Prof_Sta0)^2,IF((Q21)<=Prof_PISta,Prof_Z0+Prof_G1*((Q21)-Prof_Sta0),Prof_PIZ+Prof_G2*((Q21)-Prof_PISta))) -> 47.673
B25: Left coping (deck edge) | C25: =Deck_YL -> -6.7916667 | D25: =IF(Deck_Mode="uniform",Deck_Uni*(C25),Deck_Crown*ABS(C25)) -> -0.13583333 | E25: =E$24+$D25 -> 48.061792 | F25: =F$24+$D25 -> 48.057416 | G25: =G$24+$D25 -> 48.005891 | H25: =H$24+$D25 -> 47.954366 | I25: =I$24+$D25 -> 47.902841 | J25: =J$24+$D25 -> 47.851317 | K25: =K$24+$D25 -> 47.799792 | L25: =L$24+$D25 -> 47.748267 | ... Q25: =Q$24+$D25 -> 47.537167
B26: CL Beam 2-1 | C26: =Bm1_Off -> -4.2916667 | D26: =IF(Deck_Mode="uniform",Deck_Uni*(C26),Deck_Crown*ABS(C26)) -> -0.085833333 | E26: =E$24+$D26 -> 48.111792 | F26: =F$24+$D26 -> 48.107416 | G26: =G$24+$D26 -> 48.055891 | H26: =H$24+$D26 -> 48.004366 | I26: =I$24+$D26 -> 47.952841 | J26: =J$24+$D26 -> 47.901317 | K26: =K$24+$D26 -> 47.849792 | L26: =L$24+$D26 -> 47.798267 | ... Q26: =Q$24+$D26 -> 47.587167
B27: PGL | C27: 0 | D27: =IF(Deck_Mode="uniform",Deck_Uni*(C27),Deck_Crown*ABS(C27)) -> 0 | E27: =E$24+$D27 -> 48.197625 | F27: =F$24+$D27 -> 48.193249 | G27: =G$24+$D27 -> 48.141724 | H27: =H$24+$D27 -> 48.090199 | I27: =I$24+$D27 -> 48.038675 | J27: =J$24+$D27 -> 47.98715 | K27: =K$24+$D27 -> 47.935625 | L27: =L$24+$D27 -> 47.8841 | ... Q27: =Q$24+$D27 -> 47.673
B28: CL Beam 2-2 | C28: =Bm2_Off -> 4.2916667 | D28: =IF(Deck_Mode="uniform",Deck_Uni*(C28),Deck_Crown*ABS(C28)) -> -0.085833333 | E28: =E$24+$D28 -> 48.111792 | F28: =F$24+$D28 -> 48.107416 | G28: =G$24+$D28 -> 48.055891 | H28: =H$24+$D28 -> 48.004366 | I28: =I$24+$D28 -> 47.952841 | J28: =J$24+$D28 -> 47.901317 | K28: =K$24+$D28 -> 47.849792 | L28: =L$24+$D28 -> 47.798267 | ... Q28: =Q$24+$D28 -> 47.587167
B29: Right coping (deck edge) | C29: =Deck_YR -> 6.7916667 | D29: =IF(Deck_Mode="uniform",Deck_Uni*(C29),Deck_Crown*ABS(C29)) -> -0.13583333 | E29: =E$24+$D29 -> 48.061792 | F29: =F$24+$D29 -> 48.057416 | G29: =G$24+$D29 -> 48.005891 | H29: =H$24+$D29 -> 47.954366 | I29: =I$24+$D29 -> 47.902841 | J29: =J$24+$D29 -> 47.851317 | K29: =K$24+$D29 -> 47.799792 | L29: =L$24+$D29 -> 47.748267 | ... Q29: =Q$24+$D29 -> 47.537167
B30: Increment (ft) | C30: =Sp2_Lb/Des_FGEInc -> 10.3025

Sheet FGE Method
B1: FGE - Method
B2: Finished grade elevations at every line and station
B5: 1. Stations
B6: Each span lists its datum, the two CL bearings and equal increments between bearings (tenth points with the default 10 increments):
B11: 2. Elevations
B15: Lines are the two deck edges (copings) at y = yc +/- W/2, each beam centerline and the PGL. The FFBW columns are the PGL extended: the deck itself ends 3 in inside each FFBW (row "Deck present?"). Station labels use the notebook format (hundredths, e.g. 16+46.96).
B30: Figure 1. FGE grid for Span 1 in plan.
B31: A barrier-face (gutter) line is not tabulated: the notebook does not define the barrier. Add the barrier to the notebook CONFIG first if that line is wanted.
B32: Symbol | C32: Meaning | H32: Workbook name / location | K32: Units / value
B33: N | C33: Increments between bearings | H33: Des_FGEInc | K33: 10
B34: W, yc | C34: Deck width and center offset | H34: Deck_W, Deck_C | K34: ft
B35: δ(y) | C35: Cross-slope drop at the line offset | H35: FGE column D | K35: ft

Sheet Bearing Seats
A1: Bearing Seats | P1: Project | Q1: =""&TB_Project -> D2 I-95 Pedestrian Bridge
A2: Pad-top planes, bearing slopes, pedestal tops and pedestal corner elevations | P2: Job No. | Q2: =""&TB_JobNo
P3: Calc. by / date | Q3: =TB_CalcBy&" "&TB_CalcDate
P4: Check. by / date | Q4: =TB_CheckBy&" "&TB_CheckDate
A6: A. Seat plane at each bearing (soffit chord over the pad length)
B7: Support | C7: Span | D7: Face | E7: Beam | F7: Beam ID | G7: Offset (ft) | H7: CL brg s (ft) | I7: Pad L (in) | J7: Pad T (in) | K7: s lo (ft) | L7: s hi (ft) | M7: t lo | N7: t hi | O7: t brg | P7: Soffit @ s lo | Q7: Soffit @ s hi | R7: Soffit @ CL brg | S7: Pad-top plane (ft) | T7: Bearing slope | U7: Chord gap (in) | V7: Pedestal top @ CL brg (ft) | W7: Pad on beam
B8: End Bent 1 | C8: 1 | D8: Start | E8: 1 | F8: 1-1 | G8: =Bm1_Off -> -4.2916667 | H8: =Sp1_BrgA -> 1594.22 | I8: =EB1_PadL -> 10 | J8: =EB1_Pad -> 2.5625 | K8: =H8-I8/24 -> 1593.8033 | L8: =H8+I8/24 -> 1594.6367 | M8: =(K8-Sp1_BrgA)/Sp1_Lb -> -0.0039503832 | N8: =(L8-Sp1_BrgA)/Sp1_Lb -> 0.0039503832 | O8: =(H8-Sp1_BrgA)/Sp1_Lb -> 0 | P8: =(Sp1_ZA+(Sp1_ZB-Sp1_ZA)*(M8)-Sup_Drop+Sp1_C/3*(M8)*(1-(M8))+(Bm1_Raise)/12) -> 43.948987 | Q8: =(Sp1_ZA+(Sp1_ZB-Sp1_ZA)*(N8)-Sup_Drop+Sp1_C/3*(N8)*(1-(N8))+(Bm1_Raise)/12) -> 43.953481 | R8: =(Sp1_ZA+(Sp1_ZB-Sp1_ZA)*(O8)-Sup_Drop+Sp1_C/3*(O8)*(1-(O8))+(Bm1_Raise)/12) -> 43.951235 | S8: =(P8+Q8)/2 -> 43.951234 | T8: =(Q8-P8)/(I8/12) -> 0.0053925868 | U8: =(R8-S8)*12 -> 7.7773419e-06 | V8: =S8-J8/12 -> 43.737692 | W8: =IF(AND(K8>=Sp1_Bm0-0.000000001,L8<=Sp1_Bm1+0.000000001),"PASS","FAIL") -> PASS
B9: End Bent 1 | C9: 1 | D9: Start | E9: 2 | F9: 1-2 | G9: =Bm2_Off -> 4.2916667 | H9: =Sp1_BrgA -> 1594.22 | I9: =EB1_PadL -> 10 | J9: =EB1_Pad -> 2.5625 | K9: =H9-I9/24 -> 1593.8033 | L9: =H9+I9/24 -> 1594.6367 | M9: =(K9-Sp1_BrgA)/Sp1_Lb -> -0.0039503832 | N9: =(L9-Sp1_BrgA)/Sp1_Lb -> 0.0039503832 | O9: =(H9-Sp1_BrgA)/Sp1_Lb -> 0 | P9: =(Sp1_ZA+(Sp1_ZB-Sp1_ZA)*(M9)-Sup_Drop+Sp1_C/3*(M9)*(1-(M9))+(Bm2_Raise)/12) -> 43.948987 | Q9: =(Sp1_ZA+(Sp1_ZB-Sp1_ZA)*(N9)-Sup_Drop+Sp1_C/3*(N9)*(1-(N9))+(Bm2_Raise)/12) -> 43.953481 | R9: =(Sp1_ZA+(Sp1_ZB-Sp1_ZA)*(O9)-Sup_Drop+Sp1_C/3*(O9)*(1-(O9))+(Bm2_Raise)/12) -> 43.951235 | S9: =(P9+Q9)/2 -> 43.951234 | T9: =(Q9-P9)/(I9/12) -> 0.0053925868 | U9: =(R9-S9)*12 -> 7.7773419e-06 | V9: =S9-J9/12 -> 43.737692 | W9: =IF(AND(K9>=Sp1_Bm0-0.000000001,L9<=Sp1_Bm1+0.000000001),"PASS","FAIL") -> PASS
B10: Pier | C10: 1 | D10: End | E10: 1 | F10: 1-1 | G10: =Bm1_Off -> -4.2916667 | H10: =Sp1_BrgB -> 1699.695 | I10: =Pier_PadL -> 10 | J10: =Pier_Pad -> 2.5625 | K10: =H10-I10/24 -> 1699.2783 | L10: =H10+I10/24 -> 1700.1117 | M10: =(K10-Sp1_BrgA)/Sp1_Lb -> 0.99604962 | N10: =(L10-Sp1_BrgA)/Sp1_Lb -> 1.0039504 | O10: =(H10-Sp1_BrgA)/Sp1_Lb -> 1 | P10: =(Sp1_ZA+(Sp1_ZB-Sp1_ZA)*(M10)-Sup_Drop+Sp1_C/3*(M10)*(1-(M10))+(Bm1_Raise)/12) -> 44.476567 | Q10: =(Sp1_ZA+(Sp1_ZB-Sp1_ZA)*(N10)-Sup_Drop+Sp1_C/3*(N10)*(1-(N10))+(Bm1_Raise)/12) -> 44.480405 | R10: =(Sp1_ZA+(Sp1_ZB-Sp1_ZA)*(O10)-Sup_Drop+Sp1_C/3*(O10)*(1-(O10))+(Bm1_Raise)/12) -> 44.478487 | S10: =(P10+Q10)/2 -> 44.478486 | T10: =(Q10-P10)/(I10/12) -> 0.0046050843 | U10: =(R10-S10)*12 -> 7.7773419e-06 | V10: =S10-J10/12 -> 44.264944 | W10: =IF(AND(K10>=Sp1_Bm0-0.000000001,L10<=Sp1_Bm1+0.000000001),"PASS","FAIL") -> PASS
